Workbook

Sheet Sheet1
A1: Patient Transportation
A2: Tampa Florida Hospital
E4: Week 1 | L4: Week 2
A6: Duty | B6: Shift | C6: Name | D6: Hrs | E6: S | F6: M | G6: T | H6: W | I6: T | J6: F | K6: S | L6: S | M6: M | N6: T | O6: W | P6: T | Q6: F | R6: S
A7: Pool | B7: 7:00am-3:30pm | C7: Sheral Jones | D7: 40 | F7: 8 | G7: 8 | H7: 8 | I7: 8 | J7: 8 | M7: 8 | N7: 8 | O7: 8 | P7: 8 | Q7: 8
A8: Pool | B8: 7:00am-3:30pm | C8: William Laman | D8: 40 | F8: 8 | G8: 8 | H8: 8 | I8: 8 | J8: 8 | M8: 8 | N8: 8 | O8: 8 | P8: 8 | Q8: 8
A9: Pool | B9: 7:00am-3:30pm | C9: Nilda Milan | D9: 40 | F9: 8 | G9: 8 | H9: 8 | I9: 8 | J9: 8 | M9: 8 | N9: 8 | O9: 8 | P9: 8 | Q9: 8
A10: Pool | B10: 7:00am-3:30pm | C10: Sadie Wentworth | D10: 40 | F10: 8 | G10: 8 | H10: 8 | I10: 8 | J10: 8 | M10: 8 | N10: 8 | O10: 8 | P10: 8 | Q10: 8
A11: Pool | B11: 7:00am-3:30pm | C11: Deidra Hopkins | D11: 40 | F11: 8 | G11: 8 | H11: 8 | I11: 8 | K11: 8 | L11: 8 | N11: 8 | O11: 8 | P11: 8 | Q11: 8
A12: Pool | B12: 7:00am-3:30pm | C12: Kyra Thompson | D12: 40 | E12: 8 | G12: 8 | H12: 8 | I12: 8 | J12: 8 | M12: 8 | N12: 8 | O12: 8 | P12: 8 | R12: 8
A13: Pool | B13: 7:00am-3:30pm | C13: Mario Dunbar | D13: 40 | E13: 8 | F13: 8 | H13: 8 | I13: 8 | J13: 8 | M13: 8 | N13: 8 | O13: 8 | Q13: 8 | R13: 8
A14: Pool | B14: 7:00am-3:30pm | C14: Michelle Mongerard | D14: 40 | F14: 8 | G14: 8 | H14: 8 | J14: 8 | K14: 8 | L14: 8 | M14: 8 | N14: 8 | P14: 8 | Q14: 8
A15: Pool | B15: 7:00am-3:30pm | C15: Larryza Askew | D15: 40 | F15: 8 | G15: 8 | I15: 8 | J15: 8 | K15: 8 | L15: 8 | M15: 8 | O15: 8 | P15: 8 | Q15: 8
A16: Pool | B16: 7:00am-3:30pm | C16: Alisha Reyes | D16: 40 | G16: 8 | H16: 8 | I16: 8 | N16: 8 | O16: 8 | P16: 8
C17: Staff at 7:00am | F17: =COUNT(F7:F16) -> 8 | G17: =COUNT(G7:G16) -> 9 | H17: =COUNT(H7:H16) -> 9 | I17: =COUNT(I7:I16) -> 9 | J17: =COUNT(J7:J16) -> 8 | M17: =COUNT(M7:M16) -> 8 | N17: =COUNT(N7:N16) -> 9 | O17: =COUNT(O7:O16) -> 9 | P17: =COUNT(P7:P16) -> 9 | Q17: =COUNT(Q7:Q16) -> 8
A18: Pool | B18: 8:00am-4:30pm | C18: Michael Correa | D18: 24 | G18: 8 | I18: 8 | K18: 8 | L18: 8 | N18: 8 | P18: 8
A19: Pool | B19: 8:00am-4:30pm | C19: OPEN | D19: 32 | E19: 8 | F19: 8 | H19: 8 | J19: 8 | M19: 8 | O19: 8 | Q19: 8 | R19: 8
C20: Staff at 8:00am | F20: =COUNT(F7:F16,F18:F19) -> 9 | G20: =COUNT(G7:G16,G18:G19) -> 10 | H20: =COUNT(H7:H16,H18:H19) -> 10 | I20: =COUNT(I7:I16,I18:I19) -> 10 | J20: =COUNT(J7:J16,J18:J19) -> 9 | M20: =COUNT(M7:M16,M18:M19) -> 9 | N20: =COUNT(N7:N16,N18:N19) -> 10 | O20: =COUNT(O7:O16,O18:O19) -> 10 | P20: =COUNT(P7:P16,P18:P19) -> 10 | Q20: =COUNT(Q7:Q16,Q18:Q19) -> 9
A21: Pool | B21: 9:00am-5:30pm | C21: Aline Louis | D21: 32 | E21: 8 | F21: 8 | H21: 8 | J21: 8 | M21: 8 | O21: 8 | Q21: 8 | R21: 8
A22: Pool | B22: 9:00am-5:30pm | C22: Stephanie Millien | D22: 40 | F22: 8 | G22: 8 | I22: 8 | J22: 8 | K22: 8 | L22: 8 | N22: 8 | O22: 8 | P22: 8 | Q22: 8
C23: Staff at 9:00am | F23: =COUNT(F7:F16,F18:F19,F21:F22) -> 11 | G23: =COUNT(G7:G16,G18:G19,G21:G22) -> 11 | H23: =COUNT(H7:H16,H18:H19,H21:H22) -> 11 | I23: =COUNT(I7:I16,I18:I19,I21:I22) -> 11 | J23: =COUNT(J7:J16,J18:J19,J21:J22) -> 11 | M23: =COUNT(M7:M16,M18:M19,M21:M22) -> 10 | N23: =COUNT(N7:N16,N18:N19,N21:N22) -> 11 | O23: =COUNT(O7:O16,O18:O19,O21:O22) -> 12 | P23: =COUNT(P7:P16,P18:P19,P21:P22) -> 11 | Q23: =COUNT(Q7:Q16,Q18:Q19,Q21:Q22) -> 11
A24: Pool | B24: 11:00am-7:30pm | C24: Wesley Bullock | D24: 80 | E24: 8 | G24: 8 | H24: 8 | I24: 8 | J24: 8 | M24: 8 | N24: 8 | O24: 8 | P24: 8 | R24: 8
A25: Pool | B25: 11:00am-7:30pm | C25: Alyssa Heslin | D25: 80 | F25: 8 | G25: 8 | H25: 8 | J25: 8 | K25: 8 | L25: 8 | N25: 8 | O25: 8 | P25: 8 | Q25: 8
A26: Pool | B26: 11:00am-7:30pm | C26: Ashley Stanley | D26: 24 | F26: 8 | I26: 8 | K26: 8 | L26: 8 | M26: 8 | Q26: 8
C27: Staff at 11:00am | F27: =COUNT(F7:F16,F18:F19,F21:F22,F24:F26) -> 13 | G27: =COUNT(G7:G16,G18:G19,G21:G22,G24:G26) -> 13 | H27: =COUNT(H7:H16,H18:H19,H21:H22,H24:H26) -> 13 | I27: =COUNT(I7:I16,I18:I19,I21:I22,I24:I26) -> 13 | J27: =COUNT(J7:J16,J18:J19,J21:J22,J24:J26) -> 13 | M27: =COUNT(M7:M16,M18:M19,M21:M22,M24:M26) -> 12 | N27: =COUNT(N7:N16,N18:N19,N21:N22,N24:N26) -> 13 | O27: =COUNT(O7:O16,O18:O19,O21:O22,O24:O26) -> 14 | P27: =COUNT(P7:P16,P18:P19,P21:P22,P24:P26) -> 13 | Q27: =COUNT(Q7:Q16,Q18:Q19,Q21:Q22,Q24:Q26) -> 13
A28: Pool | B28: 1:30pm-10:00pm | C28: Jeanty Demas | D28: 40 | E28: 8 | G28: 8 | H28: 8 | I28: 8 | J28: 8 | M28: 8 | N28: 8 | O28: 8 | P28: 8 | R28: 8
A29: Pool | B29: 1:30pm-10:00pm | C29: OPEN | D29: 32 | E29: 8 | H29: 8 | I29: 8 | J29: 8 | M29: 8 | N29: 8 | Q29: 8 | R29: 8
A30: Pool | B30: 1:30pm-10:00pm | C30: Michee Louissanint | D30: 32 | F30: 8 | G30: 8 | I30: 8 | K30: 8 | L30: 8 | M30: 8 | O30: 8 | Q30: 8
A31: Pool | B31: 1:30pm-10:00pm | C31: Cody Nall | D31: 16 | E31: 8 | K31: 8 | L31: 8 | R31: 8
A32: Pool | B32: 1:30pm-10:00pm | C32: Antonio Reyes | D32: 16 | E32: 8 | K32: 8 | L32: 8 | R32: 8
C33: Staff at 1:30pm | F33: =COUNT(F7:F16,F18:F19,F21:F22,F24:F26,F28:F32) -> 14 | G33: =COUNT(G7:G16,G18:G19,G21:G22,G24:G26,G28:G32) -> 15 | H33: =COUNT(H7:H16,H18:H19,H21:H22,H24:H26,H28:H32) -> 15 | I33: =COUNT(I7:I16,I18:I19,I21:I22,I24:I26,I28:I32) -> 16 | J33: =COUNT(J7:J16,J18:J19,J21:J22,J24:J26,J28:J32) -> 15 | M33: =COUNT(M7:M16,M18:M19,M21:M22,M24:M26,M28:M32) -> 15 | N33: =COUNT(N7:N16,N18:N19,N21:N22,N24:N26,N28:N32) -> 15 | O33: =COUNT(O7:O16,O18:O19,O21:O22,O24:O26,O28:O32) -> 16 | P33: =COUNT(P7:P16,P18:P19,P21:P22,P24:P26,P28:P32) -> 14 | Q33: =COUNT(Q7:Q16,Q18:Q19,Q21:Q22,Q24:Q26,Q28:Q32) -> 15
A34: Pool | B34: 3:00pm-9:00pm | C34: Jeffery Ambriose | D34: 26 | E34: 8 | F34: 6 | G34: 6 | I34: 6 | M34: 6 | N34: 6 | P34: 6 | R34: 8
A35: Pool | B35: 3:00pm-9:00pm | C35: Anthony Miller | D35: 26 | F35: 6 | H35: 6 | J35: 6 | K35: 8 | L35: 8 | N35: 6 | O35: 6 | Q35: 6
A36: Pool | B36: 3:00pm-9:00pm | C36: Erick Polanco | D36: 28 | E36: 8 | F36: 6 | H36: 6 | K36: 8 | L36: 8 | M36: 6 | O36: 6 | R36: 8
A37: Pool | B37: 3:30pm-12:00am | C37: OPEN | D37: 32 | E37: 8 | G37: 8 | I37: 8 | J37: 8 | M37: 8 | P37: 8 | Q37: 8 | R37: 8
A38: Pool | B38: 3:30pm-12:00am | C38: Homero Saenz | D38: 40 | F38: 8 | G38: 8 | H38: 8 | J38: 8 | K38: 8 | L38: 8 | N38: 8 | O38: 8 | P38: 8 | Q38: 8
C39: Staff at 3:30pm | F39: =COUNT(F18:F19,F21:F22,F24:F26,F28:F32,F34:F38) -> 10 | G39: =COUNT(G18:G19,G21:G22,G24:G26,G28:G32,G34:G38) -> 9 | H39: =COUNT(H18:H19,H21:H22,H24:H26,H28:H32,H34:H38) -> 9 | I39: =COUNT(I18:I19,I21:I22,I24:I26,I28:I32,I34:I38) -> 9 | J39: =COUNT(J18:J19,J21:J22,J24:J26,J28:J32,J34:J38) -> 10 | M39: =COUNT(M18:M19,M21:M22,M24:M26,M28:M32,M34:M38) -> 10 | N39: =COUNT(N18:N19,N21:N22,N24:N26,N28:N32,N34:N38) -> 9 | O39: =COUNT(O18:O19,O21:O22,O24:O26,O28:O32,O34:O38) -> 10 | P39: =COUNT(P18:P19,P21:P22,P24:P26,P28:P32,P34:P38) -> 8 | Q39: =COUNT(Q18:Q19,Q21:Q22,Q24:Q26,Q28:Q32,Q34:Q38) -> 10
A40: Pool | B40: 5:00pm-10:00pm | C40: Anthena Sparks | D40: 23 | E40: 8 | G40: 5 | I40: 5 | J40: 5 | N40: 5 | P40: 5 | Q40: 5 | R40: 8
A41: Pool | B41: 5:00pm-10:00pm | C41: Deion Vazquez | D41: 23 | F41: 5 | H41: 5 | J41: 5 | K41: 8 | L41: 8 | M41: 5 | O41: 5 | Q41: 5
C42: Staff at 5:30pm | F42: =COUNT(F24:F26,F28:F32,F34:F38,F40:F41) -> 8 | G42: =COUNT(G24:G26,G28:G32,G34:G38,G40:G41) -> 8 | H42: =COUNT(H24:H26,H28:H32,H34:H38,H40:H41) -> 8 | I42: =COUNT(I24:I26,I28:I32,I34:I38,I40:I41) -> 8 | J42: =COUNT(J24:J26,J28:J32,J34:J38,J40:J41) -> 9 | M42: =COUNT(M24:M26,M28:M32,M34:M38,M40:M41) -> 9 | N42: =COUNT(N24:N26,N28:N32,N34:N38,N40:N41) -> 8 | O42: =COUNT(O24:O26,O28:O32,O34:O38,O40:O41) -> 8 | P42: =COUNT(P24:P26,P28:P32,P34:P38,P40:P41) -> 7 | Q42: =COUNT(Q24:Q26,Q28:Q32,Q34:Q38,Q40:Q41) -> 9
...

Sheet Master
A1: Patient Transportation
A2: Tampa Florida Hospital
A3: updated 6/22/17
E4: Week 1 | L4: Week 2 | S4: Week 3 | Z4: Week 4
A6: Duty | B6: Shift | C6: Name | D6: Hrs | E6: S | F6: M | G6: T | H6: W | I6: T | J6: F | K6: S | L6: S | M6: M | N6: T | O6: W | P6: T | Q6: F | R6: S | S6: S | T6: M | U6: T | V6: W | W6: T | X6: F | Y6: S | Z6: S | AA6: M | AB6: T | AC6: W | AD6: T | AE6: F | AF6: S
A7: Pool | B7: 7:00am-3:30pm | C7: Sheral Jones | D7: 40 | F7: 8 | G7: 8 | H7: 8 | I7: 8 | J7: 8 | M7: 8 | N7: 8 | O7: 8 | P7: 8 | Q7: 8 | T7: 8 | U7: 8 | V7: 8 | W7: 8 | X7: 8 | AA7: 8 | AB7: 8 | AC7: 8 | AD7: 8 | AE7: 8
A8: Pool | B8: 7:00am-3:30pm | C8: William Laman | D8: 40 | F8: 8 | G8: 8 | H8: 8 | I8: 8 | J8: 8 | M8: 8 | N8: 8 | O8: 8 | P8: 8 | Q8: 8 | T8: 8 | U8: 8 | V8: 8 | W8: 8 | X8: 8 | AA8: 8 | AB8: 8 | AC8: 8 | AD8: 8 | AE8: 8
A9: Pool | B9: 7:00am-3:30pm | C9: Nilda Milan | D9: 40 | F9: 8 | G9: 8 | H9: 8 | I9: 8 | J9: 8 | M9: 8 | N9: 8 | O9: 8 | P9: 8 | Q9: 8 | T9: 8 | U9: 8 | V9: 8 | W9: 8 | X9: 8 | AA9: 8 | AB9: 8 | AC9: 8 | AD9: 8 | AE9: 8
A10: Pool | B10: 7:00am-3:30pm | C10: Sadie Wentworth | D10: 40 | F10: 8 | G10: 8 | H10: 8 | I10: 8 | J10: 8 | M10: 8 | N10: 8 | O10: 8 | P10: 8 | Q10: 8 | T10: 8 | U10: 8 | V10: 8 | W10: 8 | X10: 8 | AA10: 8 | AB10: 8 | AC10: 8 | AD10: 8 | AE10: 8
A11: Pool | B11: 7:00am-3:30pm | C11: Deidra Hopkins | D11: 40 | F11: 8 | G11: 8 | H11: 8 | I11: 8 | K11: 8 | L11: 8 | M11: 8 | O11: 8 | P11: 8 | Q11: 8 | T11: 8 | U11: 8 | V11: 8 | W11: 8 | Y11: 8 | Z11: 8 | AA11: 8 | AC11: 8 | AD11: 8 | AE11: 8
A12: Pool | B12: 7:00am-3:30pm | C12: Athena Sparks | D12: 40 | E12: 8 | F12: 8 | G12: 8 | I12: 8 | J12: 8 | M12: 8 | N12: 8 | O12: 8 | P12: 8 | R12: 8 | S12: 8 | T12: 8 | U12: 8 | W12: 8 | X12: 8 | AA12: 8 | AB12: 8 | AC12: 8 | AD12: 8 | AF12: 8
A13: Pool | B13: 7:00am-3:30pm | C13: Mario Dunbar | D13: 40 | E13: 8 | F13: 8 | H13: 8 | I13: 8 | J13: 8 | M13: 8 | N13: 8 | O13: 8 | Q13: 8 | R13: 8 | S13: 8 | T13: 8 | V13: 8 | W13: 8 | X13: 8 | AA13: 8 | AB13: 8 | AC13: 8 | AE13: 8 | AF13: 8
A14: Pool | B14: 7:00am-3:30pm | C14: Stephanie Millien | D14: 40 | F14: 8 | G14: 8 | H14: 8 | J14: 8 | K14: 8 | M14: 8 | N14: 8 | P14: 8 | Q14: 8 | R14: 8 | T14: 8 | U14: 8 | V14: 8 | X14: 8 | Y14: 8 | AA14: 8 | AB14: 8 | AD14: 8 | AE14: 8 | AF14: 8
A15: Pool | B15: 7:00am-3:30pm | C15: Larryza Askew | D15: 40 | E15: 8 | H15: 8 | I15: 8 | J15: 8 | K15: 8 | L15: 8 | O15: 8 | P15: 8 | Q15: 8 | R15: 8 | S15: 8 | V15: 8 | W15: 8 | X15: 8 | Y15: 8 | Z15: 8 | AC15: 8 | AD15: 8 | AE15: 8 | AF15: 8
A16: Pool | B16: 7:00am-3:30pm | C16: Alisha Reyes | D16: 40 | G16: 8 | H16: 8 | I16: 8 | N16: 8 | O16: 8 | P16: 8 | U16: 8 | V16: 8 | W16: 8 | AB16: 8 | AC16: 8 | AD16: 8
C17: Staff at 7:00am | F17: =COUNT(F7:F16) -> 8 | G17: =COUNT(G7:G16) -> 8 | H17: =COUNT(H7:H16) -> 9 | I17: =COUNT(I7:I16) -> 9 | J17: =COUNT(J7:J16) -> 8 | M17: =COUNT(M7:M16) -> 8 | N17: =COUNT(N7:N16) -> 8 | O17: =COUNT(O7:O16) -> 9 | P17: =COUNT(P7:P16) -> 9 | Q17: =COUNT(Q7:Q16) -> 8 | T17: =COUNT(T7:T16) -> 8 | U17: =COUNT(U7:U16) -> 8 | V17: =COUNT(V7:V16) -> 9 | W17: =COUNT(W7:W16) -> 9 | X17: =COUNT(X7:X16) -> 8 | AA17: =COUNT(AA7:AA16) -> 8 | AB17: =COUNT(AB7:AB16) -> 8 | AC17: =COUNT(AC7:AC16) -> 9 | AD17: =COUNT(AD7:AD16) -> 9 | AE17: =COUNT(AE7:AE16) -> 8
A18: Pool | B18: 8:00am-4:30pm | C18: Brady Brooks | D18: 32 | E18: 8 | G18: 8 | I18: 8 | K18: 8 | L18: 8 | N18: 8 | P18: 8 | R18: 8 | S18: 8 | U18: 8 | W18: 8 | Y18: 8 | Z18: 8 | AB18: 8 | AD18: 8 | AF18: 8
A19: Pool | B19: 8:00am-4:30pm | C19: OPEN | D19: 24 | F19: 8 | J19: 8 | K19: 8 | L19: 8 | M19: 8 | Q19: 8 | T19: 8 | X19: 8 | Y19: 8 | Z19: 8 | AA19: 8 | AE19: 8
C20: Staff at 8:00am | F20: =COUNT(F7:F16,F18:F19) -> 9 | G20: =COUNT(G7:G16,G18:G19) -> 9 | H20: =COUNT(H7:H16,H18:H19) -> 9 | I20: =COUNT(I7:I16,I18:I19) -> 10 | J20: =COUNT(J7:J16,J18:J19) -> 9 | M20: =COUNT(M7:M16,M18:M19) -> 9 | N20: =COUNT(N7:N16,N18:N19) -> 9 | O20: =COUNT(O7:O16,O18:O19) -> 9 | P20: =COUNT(P7:P16,P18:P19) -> 10 | Q20: =COUNT(Q7:Q16,Q18:Q19) -> 9 | T20: =COUNT(T7:T16,T18:T19) -> 9 | U20: =COUNT(U7:U16,U18:U19) -> 9 | V20: =COUNT(V7:V16,V18:V19) -> 9 | W20: =COUNT(W7:W16,W18:W19) -> 10 | X20: =COUNT(X7:X16,X18:X19) -> 9 | AA20: =COUNT(AA7:AA16,AA18:AA19) -> 9 | AB20: =COUNT(AB7:AB16,AB18:AB19) -> 9 | AC20: =COUNT(AC7:AC16,AC18:AC19) -> 9 | AD20: =COUNT(AD7:AD16,AD18:AD19) -> 10 | AE20: =COUNT(AE7:AE16,AE18:AE19) -> 9
A21: Pool | B21: 9:00am-5:30pm | C21: Aline Louis | D21: 32 | E21: 8 | F21: 8 | H21: 8 | J21: 8 | L21: 8 | M21: 8 | O21: 8 | Q21: 8 | S21: 8 | T21: 8 | V21: 8 | X21: 8 | Z21: 8 | AA21: 8 | AC21: 8 | AE21: 8
A22: Pool | B22: 9:00am-5:30pm | C22: OPEN | D22: 40 | F22: 8 | G22: 8 | I22: 8 | J22: 8 | K22: 8 | N22: 8 | O22: 8 | P22: 8 | Q22: 8 | R22: 8 | T22: 8 | U22: 8 | W22: 8 | X22: 8 | Y22: 8 | AB22: 8 | AC22: 8 | AD22: 8 | AE22: 8 | AF22: 8
C23: Staff at 9:00am | F23: =COUNT(F7:F16,F18:F19,F21:F22) -> 11 | G23: =COUNT(G7:G16,G18:G19,G21:G22) -> 10 | H23: =COUNT(H7:H16,H18:H19,H21:H22) -> 10 | I23: =COUNT(I7:I16,I18:I19,I21:I22) -> 11 | J23: =COUNT(J7:J16,J18:J19,J21:J22) -> 11 | M23: =COUNT(M7:M16,M18:M19,M21:M22) -> 10 | N23: =COUNT(N7:N16,N18:N19,N21:N22) -> 10 | O23: =COUNT(O7:O16,O18:O19,O21:O22) -> 11 | P23: =COUNT(P7:P16,P18:P19,P21:P22) -> 11 | Q23: =COUNT(Q7:Q16,Q18:Q19,Q21:Q22) -> 11 | T23: =COUNT(T7:T16,T18:T19,T21:T22) -> 11 | U23: =COUNT(U7:U16,U18:U19,U21:U22) -> 10 | V23: =COUNT(V7:V16,V18:V19,V21:V22) -> 10 | W23: =COUNT(W7:W16,W18:W19,W21:W22) -> 11 | X23: =COUNT(X7:X16,X18:X19,X21:X22) -> 11 | AA23: =COUNT(AA7:AA16,AA18:AA19,AA21:AA22) -> 10 | AB23: =COUNT(AB7:AB16,AB18:AB19,AB21:AB22) -> 10 | AC23: =COUNT(AC7:AC16,AC18:AC19,AC21:AC22) -> 11 | AD23: =COUNT(AD7:AD16,AD18:AD19,AD21:AD22) -> 11 | AE23: =COUNT(AE7:AE16,AE18:AE19,AE21:AE22) -> 11
A24: Pool | B24: 11:00am-7:30pm | C24: Wesley Bullock | D24: 40 | E24: 8 | G24: 8 | H24: 8 | I24: 8 | J24: 8 | M24: 8 | N24: 8 | O24: 8 | P24: 8 | R24: 8 | S24: 8 | U24: 8 | V24: 8 | W24: 8 | X24: 8 | AA24: 8 | AB24: 8 | AC24: 8 | AD24: 8 | AF24: 8
A25: Pool | B25: 11:00am-7:30pm | C25: Alyssa Heslin | D25: 40 | F25: 8 | G25: 8 | H25: 8 | J25: 8 | K25: 8 | L25: 8 | N25: 8 | O25: 8 | P25: 8 | Q25: 8 | T25: 8 | U25: 8 | V25: 8 | X25: 8 | Y25: 8 | Z25: 8 | AB25: 8 | AC25: 8 | AD25: 8 | AE25: 8
A26: Pool | B26: 11:00am-7:30pm | C26: Ashley Stanley | D26: 24 | F26: 8 | H26: 8 | I26: 8 | L26: 8 | M26: 8 | Q26: 8 | T26: 8 | V26: 8 | W26: 8 | Z26: 8 | AA26: 8 | AE26: 8
C27: Staff at 11:00am | F27: =COUNT(F7:F16,F18:F19,F21:F22,F24:F26) -> 13 | G27: =COUNT(G7:G16,G18:G19,G21:G22,G24:G26) -> 12 | H27: =COUNT(H7:H16,H18:H19,H21:H22,H24:H26) -> 13 | I27: =COUNT(I7:I16,I18:I19,I21:I22,I24:I26) -> 13 | J27: =COUNT(J7:J16,J18:J19,J21:J22,J24:J26) -> 13 | M27: =COUNT(M7:M16,M18:M19,M21:M22,M24:M26) -> 12 | N27: =COUNT(N7:N16,N18:N19,N21:N22,N24:N26) -> 12 | O27: =COUNT(O7:O16,O18:O19,O21:O22,O24:O26) -> 13 | P27: =COUNT(P7:P16,P18:P19,P21:P22,P24:P26) -> 13 | Q27: =COUNT(Q7:Q16,Q18:Q19,Q21:Q22,Q24:Q26) -> 13 | T27: =COUNT(T7:T16,T18:T19,T21:T22,T24:T26) -> 13 | U27: =COUNT(U7:U16,U18:U19,U21:U22,U24:U26) -> 12 | V27: =COUNT(V7:V16,V18:V19,V21:V22,V24:V26) -> 13 | W27: =COUNT(W7:W16,W18:W19,W21:W22,W24:W26) -> 13 | X27: =COUNT(X7:X16,X18:X19,X21:X22,X24:X26) -> 13 | AA27: =COUNT(AA7:AA16,AA18:AA19,AA21:AA22,AA24:AA26) -> 12 | AB27: =COUNT(AB7:AB16,AB18:AB19,AB21:AB22,AB24:AB26) -> 12 | AC27: =COUNT(AC7:AC16,AC18:AC19,AC21:AC22,AC24:AC26) -> 13 | AD27: =COUNT(AD7:AD16,AD18:AD19,AD21:AD22,AD24:AD26) -> 13 | AE27: =COUNT(AE7:AE16,AE18:AE19,AE21:AE22,AE24:AE26) -> 13
A28: Pool | B28: 1:30pm-10:00pm | C28: Jeanty Demas | D28: 40 | F28: 8 | G28: 8 | H28: 8 | I28: 8 | K28: 8 | M28: 8 | N28: 8 | O28: 8 | P28: 8 | R28: 8 | T28: 8 | U28: 8 | V28: 8 | W28: 8 | Y28: 8 | AA28: 8 | AB28: 8 | AC28: 8 | AD28: 8 | AF28: 8
A29: Pool | B29: 1:30pm-10:00pm | C29: Michee Louissanint | D29: 32 | G29: 8 | I29: 8 | J29: 8 | K29: 8 | N29: 8 | P29: 8 | Q29: 8 | R29: 8 | U29: 8 | W29: 8 | X29: 8 | Y29: 8 | AB29: 8 | AD29: 8 | AE29: 8 | AF29: 8
A30: Pool | B30: 1:30pm-10:00pm | C30: Cody Nall | D30: 16 | E30: 8 | K30: 8 | L30: 8 | R30: 8 | S30: 8 | Y30: 8 | Z30: 8 | AF30: 8
A31: Pool | B31: 1:30pm-10:00pm | C31: Antonio Reyes | D31: 40 | E31: 8 | G31: 8 | H31: 8 | I31: 8 | K31: 8 | L31: 8 | M31: 8 | N31: 8 | Q31: 8 | R31: 8 | S31: 8 | U31: 8 | V31: 8 | W31: 8 | Y31: 8 | Z31: 8 | AA31: 8 | AB31: 8 | AE31: 8 | AF31: 8
C32: Staff at 1:30pm | F32: =COUNT(F7:F16,F18:F19,F21:F22,F24:F26,F28:F31) -> 14 | G32: =COUNT(G7:G16,G18:G19,G21:G22,G24:G26,G28:G31) -> 15 | H32: =COUNT(H7:H16,H18:H19,H21:H22,H24:H26,H28:H31) -> 15 | I32: =COUNT(I7:I16,I18:I19,I21:I22,I24:I26,I28:I31) -> 16 | J32: =COUNT(J7:J16,J18:J19,J21:J22,J24:J26,J28:J31) -> 14 | M32: =COUNT(M7:M16,M18:M19,M21:M22,M24:M26,M28:M31) -> 14 | N32: =COUNT(N7:N16,N18:N19,N21:N22,N24:N26,N28:N31) -> 15 | O32: =COUNT(O7:O16,O18:O19,O21:O22,O24:O26,O28:O31) -> 14 | P32: =COUNT(P7:P16,P18:P19,P21:P22,P24:P26,P28:P31) -> 15 | Q32: =COUNT(Q7:Q16,Q18:Q19,Q21:Q22,Q24:Q26,Q28:Q31) -> 15 | T32: =COUNT(T7:T16,T18:T19,T21:T22,T24:T26,T28:T31) -> 14 | U32: =COUNT(U7:U16,U18:U19,U21:U22,U24:U26,U28:U31) -> 15 | V32: =COUNT(V7:V16,V18:V19,V21:V22,V24:V26,V28:V31) -> 15 | W32: =COUNT(W7:W16,W18:W19,W21:W22,W24:W26,W28:W31) -> 16 | X32: =COUNT(X7:X16,X18:X19,X21:X22,X24:X26,X28:X31) -> 14 | AA32: =COUNT(AA7:AA16,AA18:AA19,AA21:AA22,AA24:AA26,AA28:AA31) -> 14 | AB32: =COUNT(AB7:AB16,AB18:AB19,AB21:AB22,AB24:AB26,AB28:AB31) -> 15 | AC32: =COUNT(AC7:AC16,AC18:AC19,AC21:AC22,AC24:AC26,AC28:AC31) -> 14 | AD32: =COUNT(AD7:AD16,AD18:AD19,AD21:AD22,AD24:AD26,AD28:AD31) -> 15 | AE32: =COUNT(AE7:AE16,AE18:AE19,AE21:AE22,AE24:AE26,AE28:AE31) -> 15
A33: Pool | B33: 3:00pm-9:00pm | C33: Jeffery Ambriose | D33: 26 | E33: 8 | F33: 6 | G33: 6 | I33: 6 | L33: 8 | M33: 6 | N33: 6 | P33: 6 | S33: 8 | T33: 6 | U33: 6 | W33: 6 | Z33: 8 | AA33: 6 | AB33: 6 | AD33: 6
A34: Pool | B34: 3:00pm-9:00pm | C34: Anthony Miller | D34: 26 | E34: 8 | F34: 6 | H34: 6 | J34: 6 | N34: 6 | O34: 6 | Q34: 6 | R34: 8 | S34: 8 | T34: 6 | V34: 6 | X34: 6 | AB34: 6 | AC34: 6 | AE34: 6 | AF34: 8
A35: Pool | B35: 3:00pm-9:00pm | C35: Erick Polanco | D35: 28 | E35: 8 | F35: 6 | H35: 6 | K35: 8 | L35: 8 | M35: 6 | O35: 6 | R35: 8 | S35: 8 | T35: 6 | V35: 6 | Y35: 8 | Z35: 8 | AA35: 6 | AC35: 6 | AF35: 8
A36: Pool | B36: 3:30pm-12:00am | C36: Edson Hernandez | D36: 32 | E36: 8 | G36: 8 | I36: 8 | J36: 8 | M36: 8 | P36: 8 | Q36: 8 | R36: 8 | S36: 8 | U36: 8 | W36: 8 | X36: 8 | AA36: 8 | AD36: 8 | AE36: 8 | AF36: 8
C37: Staff at 3:30pm | F37: =COUNT(F18:F19,F21:F22,F24:F26,F28:F31,F33:F36) -> 9 | G37: =COUNT(G18:G19,G21:G22,G24:G26,G28:G31,G33:G36) -> 9 | H37: =COUNT(H18:H19,H21:H22,H24:H26,H28:H31,H33:H36) -> 8 | I37: =COUNT(I18:I19,I21:I22,I24:I26,I28:I31,I33:I36) -> 9 | J37: =COUNT(J18:J19,J21:J22,J24:J26,J28:J31,J33:J36) -> 8 | M37: =COUNT(M18:M19,M21:M22,M24:M26,M28:M31,M33:M36) -> 9 | N37: =COUNT(N18:N19,N21:N22,N24:N26,N28:N31,N33:N36) -> 9 | O37: =COUNT(O18:O19,O21:O22,O24:O26,O28:O31,O33:O36) -> 7 | P37: =COUNT(P18:P19,P21:P22,P24:P26,P28:P31,P33:P36) -> 8 | Q37: =COUNT(Q18:Q19,Q21:Q22,Q24:Q26,Q28:Q31,Q33:Q36) -> 9 | T37: =COUNT(T18:T19,T21:T22,T24:T26,T28:T31,T33:T36) -> 9 | U37: =COUNT(U18:U19,U21:U22,U24:U26,U28:U31,U33:U36) -> 9 | V37: =COUNT(V18:V19,V21:V22,V24:V26,V28:V31,V33:V36) -> 8 | W37: =COUNT(W18:W19,W21:W22,W24:W26,W28:W31,W33:W36) -> 9 | X37: =COUNT(X18:X19,X21:X22,X24:X26,X28:X31,X33:X36) -> 8 | AA37: =COUNT(AA18:AA19,AA21:AA22,AA24:AA26,AA28:AA31,AA33:AA36) -> 9 | AB37: =COUNT(AB18:AB19,AB21:AB22,AB24:AB26,AB28:AB31,AB33:AB36) -> 9 | AC37: =COUNT(AC18:AC19,AC21:AC22,AC24:AC26,AC28:AC31,AC33:AC36) -> 7 | AD37: =COUNT(AD18:AD19,AD21:AD22,AD24:AD26,AD28:AD31,AD33:AD36) -> 8 | AE37: =COUNT(AE18:AE19,AE21:AE22,AE24:AE26,AE28:AE31,AE33:AE36) -> 9
A38: Pool | B38: 5:00pm-10:00pm | C38: Beverly Barthelemy | D38: 23 | E38: 8 | G38: 5 | I38: 5 | L38: 8 | N38: 5 | P38: 5 | S38: 8 | U38: 5 | W38: 5 | Z38: 8 | AB38: 5 | AD38: 5
A39: Pool | B39: 5:00pm-10:00pm | C39: Deion Vazquez | D39: 23 | F39: 5 | H39: 5 | J39: 5 | K39: 8 | L39: 8 | M39: 5 | O39: 5 | Q39: 5 | T39: 5 | V39: 5 | X39: 5 | Y39: 8 | Z39: 8 | AA39: 5 | AC39: 5 | AE39: 5
A40: Pool | B40: 5:30pm-12:30am | C40: Homero Saenz | D40: 36 | F40: 7 | G40: 7 | H40: 7 | J40: 7 | K40: 8 | L40: 8 | N40: 7 | O40: 7 | P40: 7 | Q40: 7 | T40: 7 | U40: 7 | V40: 7 | X40: 7 | Y40: 8 | Z40: 8 | AB40: 7 | AC40: 7 | AD40: 7 | AE40: 7
C41: Staff at 5:30pm | F41: =COUNT(F24:F26,F28:F31,F33:F36,F38:F40) -> 8 | G41: =COUNT(G24:G26,G28:G31,G33:G36,G38:G40) -> 9 | H41: =COUNT(H24:H26,H28:H31,H33:H36,H38:H40) -> 9 | I41: =COUNT(I24:I26,I28:I31,I33:I36,I38:I40) -> 8 | J41: =COUNT(J24:J26,J28:J31,J33:J36,J38:J40) -> 7 | M41: =COUNT(M24:M26,M28:M31,M33:M36,M38:M40) -> 8 | N41: =COUNT(N24:N26,N28:N31,N33:N36,N38:N40) -> 9 | O41: =COUNT(O24:O26,O28:O31,O33:O36,O38:O40) -> 7 | P41: =COUNT(P24:P26,P28:P31,P33:P36,P38:P40) -> 8 | Q41: =COUNT(Q24:Q26,Q28:Q31,Q33:Q36,Q38:Q40) -> 8 | T41: =COUNT(T24:T26,T28:T31,T33:T36,T38:T40) -> 8 | U41: =COUNT(U24:U26,U28:U31,U33:U36,U38:U40) -> 9 | V41: =COUNT(V24:V26,V28:V31,V33:V36,V38:V40) -> 9 | W41: =COUNT(W24:W26,W28:W31,W33:W36,W38:W40) -> 8 | X41: =COUNT(X24:X26,X28:X31,X33:X36,X38:X40) -> 7 | AA41: =COUNT(AA24:AA26,AA28:AA31,AA33:AA36,AA38:AA40) -> 8 | AB41: =COUNT(AB24:AB26,AB28:AB31,AB33:AB36,AB38:AB40) -> 9 | AC41: =COUNT(AC24:AC26,AC28:AC31,AC33:AC36,AC38:AC40) -> 7 | AD41: =COUNT(AD24:AD26,AD28:AD31,AD33:AD36,AD38:AD40) -> 8 | AE41: =COUNT(AE24:AE26,AE28:AE31,AE33:AE36,AE38:AE40) -> 8
...

Sheet HEATMAP
C2: 12/1/25-5/31/26 | D2: =31+31+28+31+30+31 -> 182 | E2: Days | J2: Total Volumes by Hour
B4: Time of Day | C4: Total Turn Time | D4: Arrival Time | E4: Trip Volume | F4: Budgeted Trips | G4: Number of Staff
B5: 0.25 | C5: 22 | D5: 13 | E5: =J5/$D$2 -> 8.8296703 | F5: =G5*2.5 -> #REF! | G5: =#REF! -> #REF! | J5: 1607
B6: 0.29166667 | C6: 26 | D6: 16 | E6: =J6/$D$2 -> 12.675824 | F6: =G6*2.5 -> #REF! | G6: =#REF! -> #REF! | J6: 2307
B7: 0.33333333 | C7: 24 | D7: 14 | E7: =J7/$D$2 -> 18.950549 | F7: =G7*2.5 -> #REF! | G7: =#REF! -> #REF! | J7: 3449
B8: 0.375 | C8: 25 | D8: 15 | E8: =J8/$D$2 -> 24.175824 | F8: =G8*2.5 -> #REF! | G8: =#REF! -> #REF! | J8: 4400
B9: 0.41666667 | C9: 25 | D9: 16 | E9: =J9/$D$2 -> 30.148352 | F9: =G9*2.5 -> #REF! | G9: =#REF! -> #REF! | J9: 5487
B10: 0.45833333 | C10: 26 | D10: 16 | E10: =J10/$D$2 -> 31.895604 | F10: =G10*2.5 -> #REF! | G10: =#REF! -> #REF! | J10: 5805
B11: 0.5 | C11: 22 | D11: 14 | E11: =J11/$D$2 -> 37.230769 | F11: =G11*2.5 -> #REF! | G11: =#REF! -> #REF! | J11: 6776
B12: 0.54166667 | C12: 20 | D12: 12 | E12: =J12/$D$2 -> 34.983516 | F12: =G12*2.5 -> #REF! | G12: =#REF! -> #REF! | J12: 6367
B13: 0.58333333 | C13: 19 | D13: 10 | E13: =J13/$D$2 -> 36.159341 | F13: =G13*2.5 -> #REF! | G13: =#REF! -> #REF! | J13: 6581
B14: 0.625 | C14: 19 | D14: 11 | E14: =J14/$D$2 -> 35.983516 | F14: =G14*2.5 -> #REF! | G14: =#REF! -> #REF! | J14: 6549
B15: 0.66666667 | C15: 21 | D15: 13 | E15: =J15/$D$2 -> 32.28022 | F15: =G15*2.5 -> #REF! | G15: =#REF! -> #REF! | J15: 5875
B16: 0.70833333 | C16: 21 | D16: 14 | E16: =J16/$D$2 -> 29.681319 | F16: =G16*2.5 -> #REF! | G16: =#REF! -> #REF! | J16: 5402
... B21: 0.91666667 | C21: 16 | D21: 10 | E21: =J21/$D$2 -> 0.78571429 | F21: =G21*2.5 -> #REF! | G21: =#REF! -> #REF! | J21: 143
B22: 0.95833333

Sheet Master as of 10.4
A1: Patient Transportation
A2: Texas Health Dallas
E4: Week 1 | L4: Week 2 | T4: Time | U4: # of Staff
E5: 46299 | F5: 46300 | G5: 46301 | H5: 46302 | I5: 46303 | J5: 46304 | K5: 46305 | L5: 46306 | M5: 46307 | N5: 46308 | O5: 46309 | P5: 46310 | Q5: 46311 | R5: 46312 | T5: 0.25 | U5: =ROUNDDOWN(MODE(E16:R16),0) -> 4
A6: Duty | B6: Shift | C6: Name | D6: Hrs | E6: S | F6: M | G6: T | H6: W | I6: T | J6: F | K6: S | L6: S | M6: M | N6: T | O6: W | P6: T | Q6: F | R6: S | T6: 0.29166667 | U6: =ROUNDDOWN(MODE(E25:R25),0) -> 8
A7: Pool | B7: 6:00am-1:30pm | C7: Kojo Boakye | D7: =SUM(E7:K7,L7:R7)/2 -> 35 | F7: 7 | G7: 7 | H7: 7 | I7: 7 | J7: 7 | M7: 7 | N7: 7 | O7: 7 | P7: 7 | Q7: 7 | T7: 0.33333333 | U7: =ROUNDDOWN(AVERAGE(E26:R26),0) -> 7
A8: Pool | B8: 6:00am-2:30pm | C8: Eddy Toledo | D8: =SUM(E8:K8,L8:R8)/2 -> 40 | F8: 8 | G8: 8 | H8: 8 | I8: 8 | K8: 8 | L8: 8 | M8: 8 | N8: 8 | P8: 8 | Q8: 8 | T8: 0.375 | U8: =ROUNDDOWN(MODE(E32:R32),0) -> 11
A9: Pool | B9: 6:00am-2:30pm | C9: Almaz Kidane | D9: =SUM(E9:K9,L9:R9)/2 -> 40 | F9: 8 | G9: 8 | H9: 8 | I9: 8 | J9: 8 | M9: 8 | N9: 8 | O9: 8 | P9: 8 | Q9: 8 | T9: 0.41666667 | U9: =ROUNDDOWN(AVERAGE(E38:R38),0) -> 11
A10: Pool | B10: 6:00am-2:30pm | C10: Marco Mendez | D10: =SUM(E10:K10,L10:R10)/2 -> 40 | E10: 8 | F10: 8 | H10: 8 | I10: 8 | J10: 8 | M10: 8 | N10: 8 | O10: 8 | P10: 8 | R10: 8 | T10: 0.45833333 | U10: =ROUNDDOWN(AVERAGE(E43:R43),0) -> 12
A11: Pool | B11: 6:00am-2:30pm | C11: Mildred Alvarado | D11: =SUM(E11:K11,L11:R11)/2 -> 40 | F11: 8 | G11: 8 | I11: 8 | J11: 8 | K11: 8 | L11: 8 | N11: 8 | O11: 8 | P11: 8 | Q11: 8 | T11: 0.5 | U11: =ROUNDDOWN(AVERAGE(E45:R45),0) -> 13
A12: Pool | B12: 6:00am-2:30pm | C12: Adhika Tahija | D12: =SUM(E12:K12,L12:R12)/2 -> 8 | E12: 8 | R12: 8 | T12: 0.54166667 | U12: =ROUNDDOWN(AVERAGE(E47:R47),0) -> 14
A13: Pool | B13: 6:00am-2:30pm | C13: Alexa Ledezma | D13: =SUM(E13:K13,L13:R13)/2 -> 8 | K13: 8 | L13: 8 | T13: 0.58333333 | U13: =ROUNDDOWN(AVERAGE(E55:R55),0) -> 16
A14: Pool | B14: 6:00am-2:30pm | C14: Aaron Hoglund | D14: =SUM(E14:K14,L14:R14)/2 -> 8 | E14: 8 | R14: 8 | T14: 0.625 | U14: =ROUNDDOWN(AVERAGE(E60:R60),0) -> 14
A15: Pool | B15: 6:00am-2:30pm | C15: Almaz Kelati | D15: =SUM(E15:K15,L15:R15)/2 -> 8 | K15: 8 | R15: 8 | T15: 0.66666667 | U15: =ROUNDDOWN(AVERAGE(E61:R61),0) -> 11
C16: Staff by 6am | E16: =COUNT(E7:E15) -> 3 | F16: =COUNT(F7:F15) -> 5 | G16: =COUNT(G7:G15) -> 4 | H16: =COUNT(H7:H15) -> 4 | I16: =COUNT(I7:I15) -> 5 | J16: =COUNT(J7:J15) -> 4 | K16: =COUNT(K7:K15) -> 4 | L16: =COUNT(L7:L15) -> 3 | ... R16: =COUNT(R7:R15) -> 4 | T16: 0.70833333 | U16: =ROUNDDOWN(AVERAGE(E62:R62),0) -> 11
A17: Pool | B17: 7:00am-3:30pm | C17: Chase Pope | D17: =SUM(E17:K17,L17:R17)/2 -> 40 | F17: 8 | H17: 8 | I17: 8 | J17: 8 | K17: 8 | L17: 8 | N17: 8 | O17: 8 | P17: 8 | Q17: 8 | T17: 0.75 | U17: =ROUNDDOWN(AVERAGE(E63:R63),0) -> 10
A18: Pool | B18: 7:00am-3:30pm | C18: Alexa Ledezma | D18: =SUM(E18:K18,L18:R18)/2 -> 32 | F18: 8 | G18: 8 | H18: 8 | I18: 8 | M18: 8 | O18: 8 | P18: 8 | Q18: 8 | T18: 0.79166667 | U18: =ROUNDDOWN(AVERAGE(E64:R64),0) -> 8
A19: Pool | B19: 7:00am-3:30pm | C19: Raquel Cardoso | D19: =SUM(E19:K19,L19:R19)/2 -> 8 | K19: 8 | R19: 8 | T19: 0.83333333 | U19: =ROUNDDOWN(AVERAGE(E65:R65),0) -> 7
A20: Open | B20: 7:00am-3:30pm | C20: Open | D20: =SUM(E20:K20,L20:R20)/2 -> 0 | T20: 0.875 | U20: =ROUNDDOWN(AVERAGE(E66:R66),0) -> 6
A21: Pool | B21: 7:00am-3:30pm | C21: Demetrius White | D21: =SUM(E21:K21,L21:R21)/2 -> 40 | E21: 8 | F21: 8 | H21: 8 | I21: 8 | J21: 8 | M21: 8 | N21: 8 | O21: 8 | Q21: 8 | R21: 8
A22: Pool | B22: 7:00am-3:30pm | C22: Esmerelda Molina | D22: =SUM(E22:K22,L22:R22)/2 -> 20 | G22: 8 | I22: 8 | J22: 8 | N22: 8 | Q22: 8 | T22: 0.91666667 | U22: =ROUNDDOWN(AVERAGE('[1]Master as of 2.17.25'!E61:R61), 0) -> 4
A23: Pool | B23: 7:00am-3:30pm | C23: Ruth Brown | D23: =SUM(E23:K23,L23:R23)/2 -> 40 | F23: 8 | G23: 8 | H23: 8 | I23: 8 | J23: 8 | M23: 8 | N23: 8 | O23: 8 | P23: 8 | Q23: 8
A24: Pool | B24: 7:30am-12:30pm | C24: Jackie Wilson | D24: =SUM(E24:K24,L24:R24)/2 -> 17.5 | E24: 5 | G24: 5 | H24: 5 | L24: 5 | M24: 5 | N24: 5 | P24: 5
C25: Staff by 7am | E25: =COUNT(E7:E15,E17:E23) -> 4 | F25: =COUNT(F7:F15,F17:F23) -> 9 | G25: =COUNT(G7:G15,G17:G23) -> 7 | H25: =COUNT(H7:H15,H17:H23) -> 8 | I25: =COUNT(I7:I15,I17:I23) -> 10 | J25: =COUNT(J7:J15,J17:J23) -> 8 | K25: =COUNT(K7:K15,K17:K23) -> 6 | L25: =COUNT(L7:L15,L17:L23) -> 4 | ... R25: =COUNT(R7:R15,R17:R23) -> 6
C26: Staff by 8am | E26: =COUNT(E7:E15,E17:E24,#REF!) -> 5 | F26: =COUNT(F7:F15,F17:F24,#REF!) -> 9 | G26: =COUNT(G7:G15,G17:G24,#REF!) -> 8 | H26: =COUNT(H7:H15,H17:H24,#REF!) -> 9 | I26: =COUNT(I7:I15,I17:I24,#REF!) -> 10 | J26: =COUNT(J7:J15,J17:J24,#REF!) -> 8 | K26: =COUNT(K7:K15,K17:K24,#REF!) -> 6 | L26: =COUNT(L7:L15,L17:L24,#REF!) -> 5 | ... R26: =COUNT(R7:R15,R17:R24,#REF!) -> 6
A27: Pool | B27: 9:00am-5:30pm | C27: Joshua Thompson | D27: =SUM(E27:K27,L27:R27)/2 -> 32 | F27: 8 | G27: 8 | I27: 8 | J27: 8 | M27: 8 | O27: 8 | P27: 8 | Q27: 8
A28: Pool | B28: 9:00am-5:30pm | C28: Adhika Tahija | D28: =SUM(E28:K28,L28:R28)/2 -> 8 | F28: 8 | M28: 8
A29: Pool | B29: 9:00am-5:30pm | C29: Aaron Hoglund | D29: =SUM(E29:K29,L29:R29)/2 -> 8 | H29: 8 | O29: 8
A30: Pool | B30: 9:00am-5:30pm | C30: Raquel Cardoso | D30: =SUM(E30:K30,L30:R30)/2 -> 16 | H30: 8 | I30: 8 | O30: 8 | P30: 8
A31: Pool | B31: 9:00am-5:30pm | C31: Gilberto Santos | D31: =SUM(E31:K31,L31:R31)/2 -> 16 | E31: 8 | K31: 8 | L31: 8 | R31: 8
C32: Staff by 9am | E32: =COUNT(E7:E15,E17:E24,#REF!,E27:E31) -> 6 | F32: =COUNT(F7:F15,F17:F24,#REF!,F27:F31) -> 11 | G32: =COUNT(G7:G15,G17:G24,#REF!,G27:G31) -> 9 | H32: =COUNT(H7:H15,H17:H24,#REF!,H27:H31) -> 11 | I32: =COUNT(I7:I15,I17:I24,#REF!,I27:I31) -> 12 | J32: =COUNT(J7:J15,J17:J24,#REF!,J27:J31) -> 9 | K32: =COUNT(K7:K15,K17:K24,#REF!,K27:K31) -> 7 | L32: =COUNT(L7:L15,L17:L24,#REF!,L27:L31) -> 6 | ... R32: =COUNT(R7:R15,R17:R24,#REF!,R27:R31) -> 7
A33: Pool | B33: 10:00am-6:30pm | C33: Adhika Tahija | D33: =SUM(E33:K33,L33:R33)/2 -> 16 | G33: 8 | J33: 8 | O33: 8 | Q33: 8
A34: Pool | B34: 10:00am-6:30pm | C34: Maxwell Miller | D34: =SUM(E34:K34,L34:R34)/2 -> 32 | F34: 8 | G34: 8 | H34: 8 | J34: 8 | M34: 8 | N34: 8 | O34: 8 | Q34: 8
A35: Pool | B35: 10:00am-6:30pm | C35: Joshua Thompson | D35: =SUM(E35:K35,L35:R35)/2 -> 8 | K35: 8 | L35: 8
A36: Pool | B36: 10:00am-6:30pm | C36: Blair Alexander | D36: =SUM(E36:K36,L36:R36)/2 -> 40 | E36: 8 | F36: 8 | H36: 8 | I36: 8 | J36: 8 | M36: 8 | N36: 8 | O36: 8 | P36: 8 | R36: 8
A37: Pool | B37: 10:00am-6:30pm | C37: Aaron Hoglund | D37: =SUM(E37:K37,L37:R37)/2 -> 24 | F37: 8 | G37: 8 | J37: 8 | M37: 8 | N37: 8 | Q37: 8
C38: Staff by 10am | E38: =COUNT(E7:E15,E17:E24,#REF!,E27:E31,E33:E37) -> 7 | F38: =COUNT(F7:F15,F17:F24,#REF!,F27:F31,F33:F37) -> 14 | G38: =COUNT(G7:G15,G17:G24,#REF!,G27:G31,G33:G37) -> 12 | H38: =COUNT(H7:H15,H17:H24,#REF!,H27:H31,H33:H37) -> 13 | I38: =COUNT(I7:I15,I17:I24,#REF!,I27:I31,I33:I37) -> 13 | J38: =COUNT(J7:J15,J17:J24,#REF!,J27:J31,J33:J37) -> 13 | K38: =COUNT(K7:K15,K17:K24,#REF!,K27:K31,K33:K37) -> 8 | L38: =COUNT(L7:L15,L17:L24,#REF!,L27:L31,L33:L37) -> 7 | ... R38: =COUNT(R7:R15,R17:R24,#REF!,R27:R31,R33:R37) -> 8
A39: Pool | B39: 11:00am-7:30pm | C39: Maxwell Miller | D39: =SUM(E39:K39,L39:R39)/2 -> 8 | K39: 8 | L39: 8
A40: Pool | B40: 11:00am-7:30pm | C40: De'Ana Humphrey | D40: =SUM(E40:K40,L40:R40)/2 -> 40 | F40: 8 | G40: 8 | I40: 8 | J40: 8 | K40: 8 | L40: 8 | N40: 8 | O40: 8 | P40: 8 | Q40: 8
A41: Pool | B41: 11:00am-7:30pm | C41: Juan Molina | D41: =SUM(E41:K41,L41:R41)/2 -> 24 | E41: 8 | H41: 8 | I41: 8 | O41: 8 | P41: 8 | R41: 8
...

Sheet Master 9.20 (Sam Edits)
A1: Patient Transportation
A2: Texas Health Dallas
E4: Week 1 | L4: Week 2 | U4: Time | V4: # of Staff
E5: 46285 | F5: 46286 | G5: 46287 | H5: 46288 | I5: 46289 | J5: 46290 | K5: 46291 | L5: 46292 | M5: 46293 | N5: 46294 | O5: 46295 | P5: 46296 | Q5: 46297 | R5: 46298 | S5: 46285 | U5: 0.25 | V5: =ROUNDDOWN(MODE(E16:R16),0) -> 4
A6: Duty | B6: Shift | C6: Name | D6: Hrs | E6: S | F6: M | G6: T | H6: W | I6: T | J6: F | K6: S | L6: S | M6: M | N6: T | O6: W | P6: T | Q6: F | R6: S | S6: S | U6: 0.29166667 | V6: =ROUNDDOWN(MODE(E25:R25),0) -> 9
A7: Pool | B7: 6:00am-1:30pm | C7: Kojo Boakye | D7: =SUM(E7:K7,L7:R7)/2 -> 35 | F7: 7 | G7: 7 | H7: 7 | I7: 7 | J7: 7 | M7: 7 | N7: 7 | O7: 7 | P7: 7 | Q7: 7 | U7: 0.33333333 | V7: =ROUNDDOWN(AVERAGE(E26:R26),0) -> 8
A8: Pool | B8: 6:00am-2:30pm | C8: Eddy Toledo | D8: =SUM(E8:K8,L8:R8)/2 -> 40 | F8: 8 | G8: 8 | H8: 8 | I8: 8 | K8: 8 | L8: 8 | M8: 8 | N8: 8 | P8: 8 | Q8: 8 | U8: 0.375 | V8: =ROUNDDOWN(MODE(E32:R32),0) -> 12
A9: Pool | B9: 6:00am-2:30pm | C9: Almaz Kidane | D9: =SUM(E9:K9,L9:R9)/2 -> 40 | F9: 8 | G9: 8 | H9: 8 | I9: 8 | J9: 8 | M9: 8 | N9: 8 | O9: 8 | P9: 8 | Q9: 8 | U9: 0.41666667 | V9: =ROUNDDOWN(AVERAGE(E38:R38),0) -> 12
A10: Pool | B10: 6:00am-2:30pm | C10: Marco Mendez | D10: =SUM(E10:K10,L10:R10)/2 -> 40 | E10: 8 | F10: 8 | H10: 8 | I10: 8 | J10: 8 | M10: 8 | N10: 8 | O10: 8 | P10: 8 | R10: 8 | S10: 8 | U10: 0.45833333 | V10: =ROUNDDOWN(AVERAGE(E43:R43),0) -> 13
A11: Pool | B11: 6:00am-2:30pm | C11: Mildred Alvarado | D11: =SUM(E11:K11,L11:R11)/2 -> 40 | F11: 8 | G11: 8 | I11: 8 | J11: 8 | K11: 8 | L11: 8 | N11: 8 | O11: 8 | P11: 8 | Q11: 8 | U11: 0.5 | V11: =ROUNDDOWN(AVERAGE(E45:R45),0) -> 14
A12: Pool | B12: 6:00am-2:30pm | C12: Adhika Tahija | D12: =SUM(E12:K12,L12:R12)/2 -> 8 | E12: 8 | R12: 8 | S12: 8 | U12: 0.54166667 | V12: =ROUNDDOWN(AVERAGE(E47:R47),0) -> 14
A13: Pool | B13: 6:00am-2:30pm | C13: Alexa Ledezma | D13: =SUM(E13:K13,L13:R13)/2 -> 8 | K13: 8 | L13: 8 | U13: 0.58333333 | V13: =ROUNDDOWN(AVERAGE(E55:R55),0) -> 17
A14: Pool | B14: 6:00am-2:30pm | C14: Aaron Hoglund | D14: =SUM(E14:K14,L14:R14)/2 -> 8 | E14: 8 | R14: 8 | S14: 8 | U14: 0.625 | V14: =ROUNDDOWN(AVERAGE(E60:R60),0) -> 15
A15: Pool | B15: 6:00am-2:30pm | C15: Almaz Kelati | D15: =SUM(E15:K15,L15:R15)/2 -> 8 | K15: 8 | R15: 8 | U15: 0.66666667 | V15: =ROUNDDOWN(AVERAGE(E61:R61),0) -> 11
C16: Staff by 6am | E16: =COUNT(E7:E15) -> 3 | F16: =COUNT(F7:F15) -> 5 | G16: =COUNT(G7:G15) -> 4 | H16: =COUNT(H7:H15) -> 4 | I16: =COUNT(I7:I15) -> 5 | J16: =COUNT(J7:J15) -> 4 | K16: =COUNT(K7:K15) -> 4 | L16: =COUNT(L7:L15) -> 3 | ... S16: =COUNT(S7:S15) -> 3 | U16: 0.70833333 | V16: =ROUNDDOWN(AVERAGE(E62:R62),0) -> 11
A17: Pool | B17: 7:00am-3:30pm | C17: Chase Pope | D17: =SUM(E17:K17,L17:R17)/2 -> 40 | F17: 8 | H17: 8 | I17: 8 | J17: 8 | K17: 8 | L17: 8 | N17: 8 | O17: 8 | P17: 8 | Q17: 8 | U17: 0.75 | V17: =ROUNDDOWN(AVERAGE(E63:R63),0) -> 10
A18: Pool | B18: 7:00am-3:30pm | C18: Alexa Ledezma | D18: =SUM(E18:K18,L18:R18)/2 -> 32 | F18: 8 | G18: 8 | H18: 8 | I18: 8 | M18: 8 | O18: 8 | P18: 8 | Q18: 8 | U18: 0.79166667 | V18: =ROUNDDOWN(AVERAGE(E64:R64),0) -> 8
A19: Pool | B19: 7:00am-3:30pm | C19: Raquel Cardoso | D19: =SUM(E19:K19,L19:R19)/2 -> 8 | K19: 8 | R19: 8 | U19: 0.83333333 | V19: =ROUNDDOWN(AVERAGE(E65:R65),0) -> 7
A20: Open | B20: 7:00am-3:30pm | C20: Open | D20: =SUM(E20:K20,L20:R20)/2 -> 32 | F20: 8 | G20: 8 | H20: 8 | K20: 8 | L20: 8 | M20: 8 | O20: 8 | P20: 8 | U20: 0.875 | V20: =ROUNDDOWN(AVERAGE(E66:R66),0) -> 6
A21: Pool | B21: 7:00am-3:30pm | C21: Demetrius White | D21: =SUM(E21:K21,L21:R21)/2 -> 40 | E21: 8 | F21: 8 | H21: 8 | I21: 8 | J21: 8 | M21: 8 | N21: 8 | O21: 8 | Q21: 8 | R21: 8 | S21: 8
A22: Pool | B22: 7:00am-3:30pm | C22: Esmerelda Molina | D22: =SUM(E22:K22,L22:R22)/2 -> 28 | E22: 8 | G22: 8 | I22: 8 | J22: 8 | N22: 8 | Q22: 8 | R22: 8 | S22: 8 | U22: 0.91666667 | V22: =ROUNDDOWN(AVERAGE('[1]Master as of 2.17.25'!E61:R61), 0) -> 4
A23: Pool | B23: 7:00am-3:30pm | C23: Ruth Brown | D23: =SUM(E23:K23,L23:R23)/2 -> 40 | F23: 8 | G23: 8 | H23: 8 | I23: 8 | J23: 8 | M23: 8 | N23: 8 | O23: 8 | P23: 8 | Q23: 8
A24: Pool | B24: 7:30am-12:30pm | C24: Jackie Wilson | D24: =SUM(E24:K24,L24:R24)/2 -> 17.5 | E24: 5 | G24: 5 | H24: 5 | L24: 5 | M24: 5 | N24: 5 | P24: 5 | S24: 5
C25: Staff by 7am | E25: =COUNT(E7:E15,E17:E23) -> 5 | F25: =COUNT(F7:F15,F17:F23) -> 10 | G25: =COUNT(G7:G15,G17:G23) -> 8 | H25: =COUNT(H7:H15,H17:H23) -> 9 | I25: =COUNT(I7:I15,I17:I23) -> 10 | J25: =COUNT(J7:J15,J17:J23) -> 8 | K25: =COUNT(K7:K15,K17:K23) -> 7 | L25: =COUNT(L7:L15,L17:L23) -> 5 | ... S25: =COUNT(S7:S15,S17:S23) -> 5
C26: Staff by 8am | E26: =COUNT(E7:E15,E17:E24,#REF!) -> 6 | F26: =COUNT(F7:F15,F17:F24,#REF!) -> 10 | G26: =COUNT(G7:G15,G17:G24,#REF!) -> 9 | H26: =COUNT(H7:H15,H17:H24,#REF!) -> 10 | I26: =COUNT(I7:I15,I17:I24,#REF!) -> 10 | J26: =COUNT(J7:J15,J17:J24,#REF!) -> 8 | K26: =COUNT(K7:K15,K17:K24,#REF!) -> 7 | L26: =COUNT(L7:L15,L17:L24,#REF!) -> 6 | ... S26: =COUNT(S7:S15,S17:S24,#REF!) -> 6
A27: Pool | B27: 9:00am-5:30pm | C27: Joshua Thompson | D27: =SUM(E27:K27,L27:R27)/2 -> 32 | F27: 8 | G27: 8 | I27: 8 | J27: 8 | M27: 8 | O27: 8 | P27: 8 | Q27: 8
A28: Pool | B28: 9:00am-5:30pm | C28: Adhika Tahija | D28: =SUM(E28:K28,L28:R28)/2 -> 8 | F28: 8 | M28: 8
A29: Pool | B29: 9:00am-5:30pm | C29: Aaron Hoglund | D29: =SUM(E29:K29,L29:R29)/2 -> 8 | H29: 8 | O29: 8
A30: Pool | B30: 9:00am-5:30pm | C30: Raquel Cardoso | D30: =SUM(E30:K30,L30:R30)/2 -> 16 | H30: 8 | I30: 8 | O30: 8 | P30: 8
A31: Pool | B31: 9:00am-5:30pm | C31: Gilberto Santos | D31: =SUM(E31:K31,L31:R31)/2 -> 16 | E31: 8 | K31: 8 | L31: 8 | R31: 8 | S31: 8
C32: Staff by 9am | E32: =COUNT(E7:E15,E17:E24,#REF!,E27:E31) -> 7 | F32: =COUNT(F7:F15,F17:F24,#REF!,F27:F31) -> 12 | G32: =COUNT(G7:G15,G17:G24,#REF!,G27:G31) -> 10 | H32: =COUNT(H7:H15,H17:H24,#REF!,H27:H31) -> 12 | I32: =COUNT(I7:I15,I17:I24,#REF!,I27:I31) -> 12 | J32: =COUNT(J7:J15,J17:J24,#REF!,J27:J31) -> 9 | K32: =COUNT(K7:K15,K17:K24,#REF!,K27:K31) -> 8 | L32: =COUNT(L7:L15,L17:L24,#REF!,L27:L31) -> 7 | ... S32: =COUNT(S7:S15,S17:S24,#REF!,S27:S31) -> 7
A33: Pool | B33: 10:00am-6:30pm | C33: Adhika Tahija | D33: =SUM(E33:K33,L33:R33)/2 -> 16 | G33: 8 | J33: 8 | O33: 8 | Q33: 8
A34: Pool | B34: 10:00am-6:30pm | C34: Maxwell Miller | D34: =SUM(E34:K34,L34:R34)/2 -> 32 | F34: 8 | G34: 8 | H34: 8 | J34: 8 | M34: 8 | N34: 8 | O34: 8 | Q34: 8
A35: Pool | B35: 10:00am-6:30pm | C35: Joshua Thompson | D35: =SUM(E35:K35,L35:R35)/2 -> 8 | K35: 8 | L35: 8
A36: Pool | B36: 10:00am-6:30pm | C36: Blair Alexander | D36: =SUM(E36:K36,L36:R36)/2 -> 40 | E36: 8 | F36: 8 | H36: 8 | I36: 8 | J36: 8 | M36: 8 | N36: 8 | O36: 8 | P36: 8 | R36: 8 | S36: 8
A37: Pool | B37: 10:00am-6:30pm | C37: Aaron Hoglund | D37: =SUM(E37:K37,L37:R37)/2 -> 24 | F37: 8 | G37: 8 | J37: 8 | M37: 8 | N37: 8 | Q37: 8
C38: Staff by 10am | E38: =COUNT(E7:E15,E17:E24,#REF!,E27:E31,E33:E37) -> 8 | F38: =COUNT(F7:F15,F17:F24,#REF!,F27:F31,F33:F37) -> 15 | G38: =COUNT(G7:G15,G17:G24,#REF!,G27:G31,G33:G37) -> 13 | H38: =COUNT(H7:H15,H17:H24,#REF!,H27:H31,H33:H37) -> 14 | I38: =COUNT(I7:I15,I17:I24,#REF!,I27:I31,I33:I37) -> 13 | J38: =COUNT(J7:J15,J17:J24,#REF!,J27:J31,J33:J37) -> 13 | K38: =COUNT(K7:K15,K17:K24,#REF!,K27:K31,K33:K37) -> 9 | L38: =COUNT(L7:L15,L17:L24,#REF!,L27:L31,L33:L37) -> 8 | ... S38: =COUNT(S7:S15,S17:S24,#REF!,S27:S31,S33:S37) -> 8
A39: Pool | B39: 11:00am-7:30pm | C39: Maxwell Miller | D39: =SUM(E39:K39,L39:R39)/2 -> 8 | K39: 8 | L39: 8
A40: Off Ext | B40: 11:00am-7:30pm | C40: De'Ana Humphrey | D40: =SUM(E40:K40,L40:R40)/2 -> 40 | F40: 8 | G40: 8 | I40: 8 | J40: 8 | K40: 8 | L40: 8 | N40: 8 | O40: 8 | P40: 8 | Q40: 8
A41: Pool | B41: 11:00am-7:30pm | C41: Juan Molina | D41: =SUM(E41:K41,L41:R41)/2 -> 24 | E41: 8 | H41: 8 | I41: 8 | O41: 8 | P41: 8 | R41: 8 | S41: 8
...

Sheet 9.21-10.2
A1: Patient Transportation
A2: Texas Health Dallas
E4: Week 1 | L4: Week 2
E5: 46285 | F5: 46286 | G5: 46287 | H5: 46288 | I5: 46289 | J5: 46290 | K5: 46291 | L5: 46292 | M5: 46293 | N5: 46294 | O5: 46295 | P5: 46296 | Q5: 46297 | R5: 46298
A6: Duty | B6: Shift | C6: Name | D6: Hrs | E6: S | F6: M | G6: T | H6: W | I6: T | J6: F | K6: S | L6: S | M6: M | N6: T | O6: W | P6: T | Q6: F | R6: S
A7: Pool | B7: 6:00am-1:30pm | C7: Kojo Boakye | D7: =SUM(E7:K7,L7:R7)/2 -> 35 | F7: 7 | G7: 7 | H7: 7 | I7: 7 | J7: 7 | M7: 7 | N7: 7 | O7: 7 | P7: 7 | Q7: 7
A8: Pool | B8: 6:00am-2:30pm | C8: Eddy Toledo | D8: =SUM(E8:K8,L8:R8)/2 -> 40 | F8: 8 | G8: 8 | H8: 8 | I8: 8 | K8: 8 | L8: 8 | M8: 8 | N8: 8 | P8: 8 | Q8: 8
A9: Pool | B9: 6:00am-2:30pm | C9: Almaz Kidane | D9: =SUM(E9:K9,L9:R9)/2 -> 40 | F9: 8 | G9: 8 | H9: 8 | I9: 8 | J9: 8 | M9: 8 | N9: 8 | O9: 8 | P9: 8 | Q9: 8
A10: Pool | B10: 6:00am-2:30pm | C10: Marco Mendez | D10: =SUM(E10:K10,L10:R10)/2 -> 36 | E10: 8 | F10: 8 | H10: 8 | I10: 8 | J10: V | M10: 8 | N10: 8 | O10: 8 | P10: 8 | R10: 8
A11: Pool | B11: 6:00am-2:30pm | C11: Mildred Alvarado | D11: =SUM(E11:K11,L11:R11)/2 -> 40 | F11: 8 | G11: 8 | I11: 8 | J11: 8 | K11: 8 | L11: 8 | N11: 8 | O11: 8 | P11: 8 | Q11: 8
A12: Pool | B12: 6:00am-2:30pm | C12: Adhika Tahija | D12: =SUM(E12:K12,L12:R12)/2 -> 8 | E12: 8 | R12: 8
A13: Pool | B13: 6:00am-2:30pm | C13: Alexa Ledezma | D13: =SUM(E13:K13,L13:R13)/2 -> 8 | K13: 8 | L13: 8
A14: Pool | B14: 6:00am-2:30pm | C14: Aaron Hoglund | D14: =SUM(E14:K14,L14:R14)/2 -> 8 | E14: 8 | R14: 8
A15: Pool | B15: 6:00am-2:30pm | C15: Almaz Kelati | D15: =SUM(E15:K15,L15:R15)/2 -> 8 | K15: 8 | R15: 8
C16: Staff by 6am | E16: =COUNT(E7:E15) -> 3 | F16: =COUNT(F7:F15) -> 5 | G16: =COUNT(G7:G15) -> 4 | H16: =COUNT(H7:H15) -> 4 | I16: =COUNT(I7:I15) -> 5 | J16: =COUNT(J7:J15) -> 3 | K16: =COUNT(K7:K15) -> 4 | L16: =COUNT(L7:L15) -> 3 | ... R16: =COUNT(R7:R15) -> 4
A17: Pool | B17: 7:00am-3:30pm | C17: Chase Pope | D17: =SUM(E17:K17,L17:R17)/2 -> 28 | F17: 8 | H17: 8 | I17: 8 | J17: V | K17: V | L17: V | N17: 8 | O17: 8 | P17: 8 | Q17: 8
A18: Pool | B18: 7:00am-3:30pm | C18: Alexa Ledezma | D18: =SUM(E18:K18,L18:R18)/2 -> 32 | F18: 8 | G18: 8 | H18: 8 | J18: 8 | M18: 8 | O18: 8 | P18: 8 | Q18: 8
A19: Pool | B19: 7:00am-3:30pm | C19: Raquel Cardoso | D19: =SUM(E19:K19,L19:R19)/2 -> 8 | K19: 8 | R19: 8
A20: Pool | B20: 7:00am-3:30pm | C20: Demetrius White | D20: =SUM(E20:K20,L20:R20)/2 -> 40 | E20: 8 | F20: 8 | H20: 8 | I20: 8 | J20: 8 | M20: 8 | N20: 8 | O20: 8 | Q20: 8 | R20: 8
A21: Pool | B21: 7:00am-3:30pm | C21: Esmerelda Molina | D21: =SUM(E21:K21,L21:R21)/2 -> 24 | E21: 8 | G21: 8 | I21: 8 | J21: V | N21: 8 | Q21: 8 | R21: 8
A22: Pool | B22: 7:00am-3:30pm | C22: Ruth Brown | D22: =SUM(E22:K22,L22:R22)/2 -> 40 | F22: 8 | G22: 8 | H22: 8 | I22: 8 | J22: 8 | M22: 8 | N22: 8 | O22: 8 | P22: 8 | Q22: 8
A23: Pool | B23: 7:30am-12:30pm | C23: Jackie Wilson | D23: =SUM(E23:K23,L23:R23)/2 -> 17.5 | E23: 5 | G23: 5 | H23: 5 | L23: 5 | M23: 5 | N23: 5 | P23: 5
C24: Staff by 7am | E24: =COUNT(E7:E15,E17:E22) -> 5 | F24: =COUNT(F7:F15,F17:F22) -> 9 | G24: =COUNT(G7:G15,G17:G22) -> 7 | H24: =COUNT(H7:H15,H17:H22) -> 8 | I24: =COUNT(I7:I15,I17:I22) -> 9 | J24: =COUNT(J7:J15,J17:J22) -> 6 | K24: =COUNT(K7:K15,K17:K22) -> 5 | L24: =COUNT(L7:L15,L17:L22) -> 3 | ... R24: =COUNT(R7:R15,R17:R22) -> 7
C25: Staff by 8am | E25: =COUNT(E7:E15,E17:E23,#REF!) -> 6 | F25: =COUNT(F7:F15,F17:F23,#REF!) -> 9 | G25: =COUNT(G7:G15,G17:G23,#REF!) -> 8 | H25: =COUNT(H7:H15,H17:H23,#REF!) -> 9 | I25: =COUNT(I7:I15,I17:I23,#REF!) -> 9 | J25: =COUNT(J7:J15,J17:J23,#REF!) -> 6 | K25: =COUNT(K7:K15,K17:K23,#REF!) -> 5 | L25: =COUNT(L7:L15,L17:L23,#REF!) -> 4 | ... R25: =COUNT(R7:R15,R17:R23,#REF!) -> 7
A26: Pool | B26: 9:00am-5:30pm | C26: Joshua Thompson | D26: =SUM(E26:K26,L26:R26)/2 -> 32 | F26: 8 | G26: 8 | I26: 8 | J26: 8 | M26: 8 | O26: 8 | P26: 8 | Q26: 8
A27: Pool | B27: 9:00am-5:30pm | C27: Adhika Tahija | D27: =SUM(E27:K27,L27:R27)/2 -> 8 | F27: 8 | M27: 8
A28: Pool | B28: 9:00am-5:30pm | C28: Aaron Hoglund | D28: =SUM(E28:K28,L28:R28)/2 -> 8 | H28: 8 | O28: 8
A29: Pool | B29: 9:00am-5:30pm | C29: Raquel Cardoso | D29: =SUM(E29:K29,L29:R29)/2 -> 16 | H29: 8 | I29: 8 | O29: 8 | P29: 8
A30: Pool | B30: 9:00am-5:30pm | C30: Gilberto Santos | D30: =SUM(E30:K30,L30:R30)/2 -> 16 | E30: 8 | K30: 8 | L30: 8 | R30: 8
C31: Staff by 9am | E31: =COUNT(E7:E15,E17:E23,#REF!,E26:E30) -> 7 | F31: =COUNT(F7:F15,F17:F23,#REF!,F26:F30) -> 11 | G31: =COUNT(G7:G15,G17:G23,#REF!,G26:G30) -> 9 | H31: =COUNT(H7:H15,H17:H23,#REF!,H26:H30) -> 11 | I31: =COUNT(I7:I15,I17:I23,#REF!,I26:I30) -> 11 | J31: =COUNT(J7:J15,J17:J23,#REF!,J26:J30) -> 7 | K31: =COUNT(K7:K15,K17:K23,#REF!,K26:K30) -> 6 | L31: =COUNT(L7:L15,L17:L23,#REF!,L26:L30) -> 5 | ... R31: =COUNT(R7:R15,R17:R23,#REF!,R26:R30) -> 8
A32: Pool | B32: 10:00am-6:30pm | C32: Adhika Tahija | D32: =SUM(E32:K32,L32:R32)/2 -> 16 | G32: 8 | J32: 8 | O32: 8 | Q32: 8
A33: Pool | B33: 10:00am-6:30pm | C33: Maxwell Miller | D33: =SUM(E33:K33,L33:R33)/2 -> 32 | F33: 8 | G33: 8 | H33: 8 | J33: 8 | M33: 8 | N33: 8 | O33: 8 | Q33: 8
A34: Pool | B34: 10:00am-6:30pm | C34: Joshua Thompson | D34: =SUM(E34:K34,L34:R34)/2 -> 8 | K34: 8 | L34: 8
A35: Pool | B35: 10:00am-6:30pm | C35: Blair Alexander | D35: =SUM(E35:K35,L35:R35)/2 -> 36 | E35: V | F35: 8 | H35: 8 | I35: 8 | J35: 8 | M35: 8 | N35: 8 | O35: 8 | P35: 8 | R35: 8
A36: Pool | B36: 10:00am-6:30pm | C36: Aaron Hoglund | D36: =SUM(E36:K36,L36:R36)/2 -> 24 | F36: 8 | G36: 8 | J36: 8 | M36: 8 | N36: 8 | Q36: 8
C37: Staff by 10am | E37: =COUNT(E7:E15,E17:E23,#REF!,E26:E30,E32:E36) -> 7 | F37: =COUNT(F7:F15,F17:F23,#REF!,F26:F30,F32:F36) -> 14 | G37: =COUNT(G7:G15,G17:G23,#REF!,G26:G30,G32:G36) -> 12 | H37: =COUNT(H7:H15,H17:H23,#REF!,H26:H30,H32:H36) -> 13 | I37: =COUNT(I7:I15,I17:I23,#REF!,I26:I30,I32:I36) -> 12 | J37: =COUNT(J7:J15,J17:J23,#REF!,J26:J30,J32:J36) -> 11 | K37: =COUNT(K7:K15,K17:K23,#REF!,K26:K30,K32:K36) -> 7 | L37: =COUNT(L7:L15,L17:L23,#REF!,L26:L30,L32:L36) -> 6 | ... R37: =COUNT(R7:R15,R17:R23,#REF!,R26:R30,R32:R36) -> 9
A38: Pool | B38: 11:00am-7:30pm | C38: Maxwell Miller | D38: =SUM(E38:K38,L38:R38)/2 -> 8 | K38: 8 | L38: 8
A39: TRAIN | B39: 11:00am-7:30pm | C39: De'Ana Humphrey | D39: =SUM(E39:K39,L39:R39)/2 -> 24 | G39: T | H39: T | I39: T | J39: T | K39: 8 | M39: 8 | N39: 8 | O39: 8 | P39: 8 | Q39: 8
A40: Pool | B40: 11:00am-7:30pm | C40: Juan Molina | D40: =SUM(E40:K40,L40:R40)/2 -> 16 | E40: 8 | H40: V | I40: V | O40: 8 | P40: 8 | R40: 8
A41: Pool | B41: 11:30am-10:00pm | C41: Eduardo Lopez | D41: =SUM(E41:K41,L41:R41)/2 -> 30 | E41: 10 | J41: 10 | K41: 10 | L41: 10 | Q41: 10 | R41: 10
...

Sheet 9.6-9.19
A1: Patient Transportation
A2: Texas Health Dallas
E4: Week 1 | L4: Week 2 | T4: Time | U4: # of Staff
E5: 46271 | F5: HOL | G5: 46273 | H5: 46274 | I5: 46275 | J5: 46276 | K5: 46277 | L5: 46278 | M5: 46279 | N5: 46280 | O5: 46281 | P5: 46282 | Q5: 46283 | R5: 46284 | T5: 0.25 | U5: =ROUNDDOWN(AVERAGE(E16:R16),0) -> 3
A6: Duty | B6: Shift | C6: Name | D6: Hrs | E6: S | F6: M | G6: T | H6: W | I6: T | J6: F | K6: S | L6: S | M6: M | N6: T | O6: W | P6: T | Q6: F | R6: S | T6: 0.29166667 | U6: =ROUNDDOWN(AVERAGE(E24:R24),0) -> 6
A7: Pool | B7: 6:00am-1:30pm | C7: Kojo Boakye | D7: =SUM(E7:K7,L7:R7)/2 -> 35.5 | F7: 8 | G7: 7 | H7: 7 | I7: 7 | J7: 7 | M7: 7 | N7: 7 | O7: 7 | P7: 7 | Q7: 7 | T7: 0.33333333 | U7: =ROUNDDOWN(AVERAGE(E25:R25),0) -> 7
A8: Pool | B8: 6:00am-2:30pm | C8: Eddy Toledo | D8: =SUM(E8:K8,L8:R8)/2 -> 36 | G8: 8 | H8: 8 | J8: 8 | K8: 8 | L8: 8 | M8: 8 | N8: 8 | P8: 8 | Q8: 8 | T8: 0.375 | U8: =ROUNDDOWN(AVERAGE(E31:R31),0) -> 8
A9: Pool | B9: 6:00am-2:30pm | C9: Almaz Kidane | D9: =SUM(E9:K9,L9:R9)/2 -> 20 | G9: 8 | H9: 8 | I9: 8 | J9: V | M9: V | N9: V | O9: V | P9: 8 | Q9: 8 | T9: 0.41666667 | U9: =ROUNDDOWN(AVERAGE(E37:R37),0) -> 10
A10: Pool | B10: 6:00am-2:30pm | C10: Marco Mendez | D10: =SUM(E10:K10,L10:R10)/2 -> 36 | E10: V | G10: 8 | H10: 8 | I10: 8 | J10: 8 | M10: 8 | N10: 8 | O10: 8 | Q10: 8 | R10: 8 | T10: 0.45833333 | U10: =ROUNDDOWN(AVERAGE(E42:R42),0) -> 10
A11: Pool | B11: 6:00am-2:30pm | C11: Mildred Alvarado | D11: =SUM(E11:K11,L11:R11)/2 -> 40 | F11: 8 | G11: 8 | I11: 8 | J11: 8 | K11: 8 | L11: 8 | N11: 8 | O11: 8 | P11: 8 | Q11: 8 | T11: 0.5 | U11: =ROUNDDOWN(AVERAGE(E44:R44),0) -> 11
A12: Pool | B12: 6:00am-2:30pm | C12: Adhika Tahija | D12: =SUM(E12:K12,L12:R12)/2 -> 8 | E12: 8 | F12: 8 | R12: V | T12: 0.54166667 | U12: =ROUNDDOWN(AVERAGE(E46:R46),0) -> 11
A13: Pool | B13: 6:00am-2:30pm | C13: Alexa Ledezma | D13: =SUM(E13:K13,L13:R13)/2 -> 8 | K13: 8 | L13: 8 | T13: 0.58333333 | U13: =ROUNDDOWN(AVERAGE(E56:R56),0) -> 13
A14: Pool | B14: 6:00am-2:30pm | C14: Aaron Hoglund | D14: =SUM(E14:K14,L14:R14)/2 -> 8 | E14: 8 | R14: 8 | T14: 0.625 | U14: =ROUNDDOWN(AVERAGE(E61:R61),0) -> 11
A15: Pool | B15: 6:00am-2:30pm | C15: Almaz Kelati | D15: =SUM(E15:K15,L15:R15)/2 -> 12 | F15: 8 | K15: 8 | R15: 8 | T15: 0.66666667 | U15: =ROUNDDOWN(AVERAGE(E62:R62),0) -> 8
C16: Staff by 6am | E16: =COUNT(E7:E15) -> 2 | F16: =COUNT(F7:F15) -> 4 | G16: =COUNT(G7:G15) -> 5 | H16: =COUNT(H7:H15) -> 4 | I16: =COUNT(I7:I15) -> 4 | J16: =COUNT(J7:J15) -> 4 | K16: =COUNT(K7:K15) -> 4 | L16: =COUNT(L7:L15) -> 3 | ... R16: =COUNT(R7:R15) -> 3 | T16: 0.70833333 | U16: =ROUNDDOWN(AVERAGE(E63:R63),0) -> 8
A17: Pool | B17: 7:00am-3:30pm | C17: Chase Pope | D17: =SUM(E17:K17,L17:R17)/2 -> 28 | I17: 8 | J17: 8 | K17: 8 | L17: 8 | N17: 8 | O17: 8 | Q17: 8 | T17: 0.75 | U17: =ROUNDDOWN(AVERAGE(E64:R64),0) -> 7
A18: Pool | B18: 7:00am-3:30pm | C18: Alexa Ledezma | D18: =SUM(E18:K18,L18:R18)/2 -> 28 | G18: 8 | H18: 8 | I18: 8 | M18: 8 | O18: 8 | P18: 8 | Q18: 8 | T18: 0.79166667 | U18: =ROUNDDOWN(AVERAGE(E65:R65),0) -> 5
A19: Pool | B19: 7:00am-3:30pm | C19: Raquel Cardoso | D19: =SUM(E19:K19,L19:R19)/2 -> 8 | K19: 8 | R19: 8 | T19: 0.83333333 | U19: =ROUNDDOWN(AVERAGE(E66:R66),0) -> 5
A20: Pool | B20: 7:00am-3:30pm | C20: Demetrius White | D20: =SUM(E20:K20,L20:R20)/2 -> 40 | E20: 8 | F20: 8 | H20: 8 | I20: 8 | J20: 8 | M20: 8 | N20: 8 | O20: 8 | Q20: 8 | R20: 8 | T20: 0.875 | U20: =ROUNDDOWN(AVERAGE(E67:R67),0) -> 5
A21: Pool | B21: 7:00am-3:30pm | C21: Esmerelda Molina | D21: =SUM(E21:K21,L21:R21)/2 -> 28 | E21: 8 | G21: 8 | I21: 8 | J21: 8 | N21: 8 | Q21: 8 | R21: 8
A22: Pool | B22: 7:00am-3:30pm | C22: Ruth Brown | D22: =SUM(E22:K22,L22:R22)/2 -> 36 | G22: 8 | H22: 8 | I22: 8 | J22: 8 | M22: 8 | N22: 8 | O22: 8 | P22: 8 | Q22: 8 | T22: 0.91666667 | U22: =ROUNDDOWN(AVERAGE('[1]Master as of 2.17.25'!E61:R61), 0) -> 4
A23: Pool | B23: 7:30am-12:30pm | C23: Jackie Wilson | D23: =SUM(E23:K23,L23:R23)/2 -> 17.5 | E23: 5 | G23: 5 | H23: 5 | L23: 5 | M23: 5 | N23: 5 | P23: 5
C24: Staff by 7am | E24: =COUNT(E7:E15,E17:E22) -> 4 | F24: =COUNT(F7:F15,F17:F22) -> 5 | G24: =COUNT(G7:G15,G17:G22) -> 8 | H24: =COUNT(H7:H15,H17:H22) -> 7 | I24: =COUNT(I7:I15,I17:I22) -> 9 | J24: =COUNT(J7:J15,J17:J22) -> 8 | K24: =COUNT(K7:K15,K17:K22) -> 6 | L24: =COUNT(L7:L15,L17:L22) -> 4 | ... R24: =COUNT(R7:R15,R17:R22) -> 6
C25: Staff by 8am | E25: =COUNT(E7:E15,E17:E23,#REF!) -> 5 | F25: =COUNT(F7:F15,F17:F23,#REF!) -> 5 | G25: =COUNT(G7:G15,G17:G23,#REF!) -> 9 | H25: =COUNT(H7:H15,H17:H23,#REF!) -> 8 | I25: =COUNT(I7:I15,I17:I23,#REF!) -> 9 | J25: =COUNT(J7:J15,J17:J23,#REF!) -> 8 | K25: =COUNT(K7:K15,K17:K23,#REF!) -> 6 | L25: =COUNT(L7:L15,L17:L23,#REF!) -> 5 | ... R25: =COUNT(R7:R15,R17:R23,#REF!) -> 6
A26: Pool | B26: 9:00am-5:30pm | C26: Joshua Thompson | D26: =SUM(E26:K26,L26:R26)/2 -> 28 | G26: 8 | H26: 8 | I26: 8 | M26: 8 | O26: 8 | P26: 8 | Q26: 8
A27: Pool | B27: 9:00am-5:30pm | C27: Adhika Tahija | D27: =SUM(E27:K27,L27:R27)/2 -> 4 | M27: 8
A28: Pool | B28: 9:00am-5:30pm | C28: Aaron Hoglund | D28: =SUM(E28:K28,L28:R28)/2 -> 8 | H28: 8 | O28: 8
A29: Pool | B29: 9:00am-5:30pm | C29: Raquel Cardoso | D29: =SUM(E29:K29,L29:R29)/2 -> 16 | H29: 8 | I29: 8 | O29: 8 | P29: 8
A30: Pool | B30: 9:00am-5:30pm | C30: Gilberto Santos | D30: =SUM(E30:K30,L30:R30)/2 -> 16 | E30: 8 | K30: 8 | L30: 8 | R30: 8
C31: Staff by 9am | E31: =COUNT(E7:E15,E17:E23,#REF!,E26:E30) -> 6 | F31: =COUNT(F7:F15,F17:F23,#REF!,F26:F30) -> 5 | G31: =COUNT(G7:G15,G17:G23,#REF!,G26:G30) -> 10 | H31: =COUNT(H7:H15,H17:H23,#REF!,H26:H30) -> 11 | I31: =COUNT(I7:I15,I17:I23,#REF!,I26:I30) -> 11 | J31: =COUNT(J7:J15,J17:J23,#REF!,J26:J30) -> 8 | K31: =COUNT(K7:K15,K17:K23,#REF!,K26:K30) -> 7 | L31: =COUNT(L7:L15,L17:L23,#REF!,L26:L30) -> 6 | ... R31: =COUNT(R7:R15,R17:R23,#REF!,R26:R30) -> 7
A32: Pool | B32: 10:00am-6:30pm | C32: Adhika Tahija | D32: =SUM(E32:K32,L32:R32)/2 -> 12 | G32: 8 | J32: 8 | O32: 8 | Q32: V | R32: V
A33: Pool | B33: 10:00am-6:30pm | C33: Maxwell Miller | D33: =SUM(E33:K33,L33:R33)/2 -> 32 | F33: 8 | G33: 8 | H33: 8 | J33: 8 | M33: 8 | N33: 8 | O33: 8 | Q33: 8
A34: Pool | B34: 10:00am-6:30pm | C34: Joshua Thompson | D34: =SUM(E34:K34,L34:R34)/2 -> 8 | K34: 8 | L34: 8
A35: Pool | B35: 10:00am-6:30pm | C35: Blair Alexander | D35: =SUM(E35:K35,L35:R35)/2 -> 36 | E35: 8 | G35: 8 | H35: 8 | I35: 8 | J35: 8 | M35: 8 | N35: 8 | O35: 8 | P35: 8 | R35: V
A36: Pool | B36: 10:00am-6:30pm | C36: Aaron Hoglund | D36: =SUM(E36:K36,L36:R36)/2 -> 24 | F36: 8 | G36: 8 | J36: 8 | M36: 8 | N36: 8 | Q36: 8
C37: Staff by 10am | E37: =COUNT(E7:E15,E17:E23,#REF!,E26:E30,E32:E36) -> 7 | F37: =COUNT(F7:F15,F17:F23,#REF!,F26:F30,F32:F36) -> 7 | G37: =COUNT(G7:G15,G17:G23,#REF!,G26:G30,G32:G36) -> 14 | H37: =COUNT(H7:H15,H17:H23,#REF!,H26:H30,H32:H36) -> 13 | I37: =COUNT(I7:I15,I17:I23,#REF!,I26:I30,I32:I36) -> 12 | J37: =COUNT(J7:J15,J17:J23,#REF!,J26:J30,J32:J36) -> 12 | K37: =COUNT(K7:K15,K17:K23,#REF!,K26:K30,K32:K36) -> 8 | L37: =COUNT(L7:L15,L17:L23,#REF!,L26:L30,L32:L36) -> 7 | ... R37: =COUNT(R7:R15,R17:R23,#REF!,R26:R30,R32:R36) -> 7
A38: Pool | B38: 11:00am-7:30pm | C38: Maxwell Miller | D38: =SUM(E38:K38,L38:R38)/2 -> 8 | K38: 8 | L38: 8
A39: Off Ext | B39: 11:00am-7:30pm | C39: De'Ana Humphrey | D39: =SUM(E39:K39,L39:R39)/2 -> 0
A40: Pool | B40: 11:00am-7:30pm | C40: Juan Molina | D40: =SUM(E40:K40,L40:R40)/2 -> 16 | E40: 8 | H40: 8 | I40: 8 | O40: V | P40: V | R40: 8
A41: Pool | B41: 11:30am-10:00pm | C41: Eduardo Lopez | D41: =SUM(E41:K41,L41:R41)/2 -> 30 | E41: 10 | J41: 10 | K41: 10 | L41: 10 | Q41: 10 | R41: 10
...

Sheet 8.23-9.5
A1: Patient Transportation
A2: Texas Health Dallas
E4: Week 1 | L4: Week 2 | T4: Time | U4: # of Staff
E5: 46257 | F5: 46258 | G5: 46259 | H5: 46260 | I5: 46261 | J5: 46262 | K5: 46263 | L5: 46264 | M5: 46265 | N5: 46266 | O5: 46267 | P5: 46268 | Q5: 46269 | R5: 46270 | T5: 0.25 | U5: =ROUNDDOWN(AVERAGE(E16:R16),0) -> 3
A6: Duty | B6: Shift | C6: Name | D6: Hrs | E6: S | F6: M | G6: T | H6: W | I6: T | J6: F | K6: S | L6: S | M6: M | N6: T | O6: W | P6: T | Q6: F | R6: S | T6: 0.29166667 | U6: =ROUNDDOWN(AVERAGE(E25:R25),0) -> 7
A7: Pool | B7: 6:00am-1:30pm | C7: Kojo Boakye | D7: =SUM(E7:K7,L7:R7)/2 -> 35 | F7: 7 | G7: 7 | H7: 7 | I7: 7 | J7: 7 | M7: 7 | N7: 7 | O7: 7 | P7: 7 | Q7: 7 | T7: 0.33333333 | U7: =ROUNDDOWN(AVERAGE(E26:R26),0) -> 7
A8: Pool | B8: 6:00am-2:30pm | C8: Eddy Toledo | D8: =SUM(E8:K8,L8:R8)/2 -> 40 | F8: 8 | G8: 8 | H8: 8 | J8: 8 | K8: 8 | L8: 8 | M8: 8 | N8: 8 | P8: 8 | Q8: 8 | T8: 0.375 | U8: =ROUNDDOWN(AVERAGE(E32:R32),0) -> 8
A9: Pool | B9: 6:00am-2:30pm | C9: Almaz Kidane | D9: =SUM(E9:K9,L9:R9)/2 -> 40 | F9: 8 | G9: 8 | H9: 8 | I9: 8 | J9: 8 | M9: 8 | N9: 8 | O9: 8 | P9: 8 | Q9: 8 | T9: 0.41666667 | U9: =ROUNDDOWN(AVERAGE(E38:R38),0) -> 11
A10: Pool | B10: 6:00am-2:30pm | C10: Marco Mendez | D10: =SUM(E10:K10,L10:R10)/2 -> 32 | E10: 8 | G10: 8 | H10: 8 | I10: 8 | J10: 8 | M10: 8 | N10: 8 | O10: 8 | Q10: V | R10: V | T10: 0.45833333 | U10: =ROUNDDOWN(AVERAGE(E43:R43),0) -> 11
A11: Pool | B11: 6:00am-2:30pm | C11: Mildred Alvarado | D11: =SUM(E11:K11,L11:R11)/2 -> 32 | F11: V | G11: V | I11: 8 | J11: 8 | K11: 8 | L11: 8 | N11: 8 | O11: 8 | P11: 8 | Q11: 8 | T11: 0.5 | U11: =ROUNDDOWN(AVERAGE(E44:R44),0) -> 12
A12: Pool | B12: 6:00am-2:30pm | C12: Adhika Tahija | D12: =SUM(E12:K12,L12:R12)/2 -> 8 | E12: 8 | R12: 8 | T12: 0.54166667 | U12: =ROUNDDOWN(AVERAGE(E46:R46),0) -> 12
A13: Pool | B13: 6:00am-2:30pm | C13: Alexa Ledezma | D13: =SUM(E13:K13,L13:R13)/2 -> 8 | K13: 8 | L13: 8 | T13: 0.58333333 | U13: =ROUNDDOWN(AVERAGE(E55:R55),0) -> 14
A14: Pool | B14: 6:00am-2:30pm | C14: Aaron Hoglund | D14: =SUM(E14:K14,L14:R14)/2 -> 8 | E14: 8 | R14: 8 | T14: 0.625 | U14: =ROUNDDOWN(AVERAGE(E60:R60),0) -> 12
A15: Pool | B15: 6:00am-2:30pm | C15: Almaz Kelati | D15: =SUM(E15:K15,L15:R15)/2 -> 8 | K15: 8 | R15: 8 | T15: 0.66666667 | U15: =ROUNDDOWN(AVERAGE(E61:R61),0) -> 9
C16: Staff by 6am | E16: =COUNT(E7:E15) -> 3 | F16: =COUNT(F7:F15) -> 3 | G16: =COUNT(G7:G15) -> 4 | H16: =COUNT(H7:H15) -> 4 | I16: =COUNT(I7:I15) -> 4 | J16: =COUNT(J7:J15) -> 5 | K16: =COUNT(K7:K15) -> 4 | L16: =COUNT(L7:L15) -> 3 | ... R16: =COUNT(R7:R15) -> 3 | T16: 0.70833333 | U16: =ROUNDDOWN(AVERAGE(E62:R62),0) -> 9
A17: Pool | B17: 7:00am-3:30pm | C17: Chase Pope | D17: =SUM(E17:K17,L17:R17)/2 -> 40 | F17: 8 | H17: 8 | I17: 8 | J17: 8 | K17: 8 | L17: 8 | N17: 8 | O17: 8 | P17: 8 | Q17: 8 | T17: 0.75 | U17: =ROUNDDOWN(AVERAGE(E63:R63),0) -> 8
A18: Pool | B18: 7:00am-3:30pm | C18: Alexa Ledezma | D18: =SUM(E18:K18,L18:R18)/2 -> 28 | F18: 8 | G18: 8 | H18: 8 | I18: 8 | M18: 8 | O18: 8 | P18: 8 | Q18: V | T18: 0.79166667 | U18: =ROUNDDOWN(AVERAGE(E64:R64),0) -> 6
A19: Pool | B19: 7:00am-3:30pm | C19: Raquel Cardoso | D19: =SUM(E19:K19,L19:R19)/2 -> 8 | K19: 8 | R19: 8 | T19: 0.83333333 | U19: =ROUNDDOWN(AVERAGE(E65:R65),0) -> 5
A20: Off Ext | B20: 7:00am-3:30pm | C20: Peter Hughes | T20: 0.875 | U20: =ROUNDDOWN(AVERAGE(E66:R66),0) -> 5
A21: Pool | B21: 7:00am-3:30pm | C21: Demetrius White | D21: =SUM(E21:K21,L21:R21)/2 -> 32 | E21: V | F21: V | H21: 8 | I21: 8 | J21: 8 | M21: 8 | N21: 8 | O21: 8 | Q21: 8 | R21: 8
A22: Pool | B22: 7:00am-3:30pm | C22: Esmerelda Molina | D22: =SUM(E22:K22,L22:R22)/2 -> 28 | E22: 8 | G22: 8 | I22: 8 | J22: 8 | N22: 8 | P22: 8 | Q22: 8 | T22: 0.91666667 | U22: =ROUNDDOWN(AVERAGE('[1]Master as of 2.17.25'!E61:R61), 0) -> 4
A23: Pool | B23: 7:00am-3:30pm | C23: Ruth Brown | D23: =SUM(E23:K23,L23:R23)/2 -> 40 | F23: 8 | G23: 8 | H23: 8 | I23: 8 | J23: 8 | M23: 8 | N23: 8 | O23: 8 | P23: 8 | Q23: 8
A24: Pool | B24: 7:30am-12:30pm | C24: Jackie Wilson | D24: =SUM(E24:K24,L24:R24)/2 -> 17.5 | E24: 5 | F24: 5 | G24: V | H24: 5 | L24: 5 | M24: 5 | N24: 5 | P24: 5
C25: Staff by 7am | E25: =COUNT(E7:E15,E17:E23) -> 4 | F25: =COUNT(F7:F15,F17:F23) -> 6 | G25: =COUNT(G7:G15,G17:G23) -> 7 | H25: =COUNT(H7:H15,H17:H23) -> 8 | I25: =COUNT(I7:I15,I17:I23) -> 9 | J25: =COUNT(J7:J15,J17:J23) -> 9 | K25: =COUNT(K7:K15,K17:K23) -> 6 | L25: =COUNT(L7:L15,L17:L23) -> 4 | ... R25: =COUNT(R7:R15,R17:R23) -> 5
C26: Staff by 8am | E26: =COUNT(E7:E15,E17:E24,#REF!) -> 5 | F26: =COUNT(F7:F15,F17:F24,#REF!) -> 7 | G26: =COUNT(G7:G15,G17:G24,#REF!) -> 7 | H26: =COUNT(H7:H15,H17:H24,#REF!) -> 9 | I26: =COUNT(I7:I15,I17:I24,#REF!) -> 9 | J26: =COUNT(J7:J15,J17:J24,#REF!) -> 9 | K26: =COUNT(K7:K15,K17:K24,#REF!) -> 6 | L26: =COUNT(L7:L15,L17:L24,#REF!) -> 5 | ... R26: =COUNT(R7:R15,R17:R24,#REF!) -> 5
A27: Pool | B27: 9:00am-5:30pm | C27: Joshua Thompson | D27: =SUM(E27:K27,L27:R27)/2 -> 32 | F27: 8 | G27: 8 | H27: 8 | I27: 8 | M27: 8 | O27: 8 | P27: 8 | Q27: 8
A28: Pool | B28: 9:00am-5:30pm | C28: Adhika Tahija | D28: =SUM(E28:K28,L28:R28)/2 -> 8 | F28: 8 | M28: 8
A29: Pool | B29: 9:00am-5:30pm | C29: Aaron Hoglund | D29: =SUM(E29:K29,L29:R29)/2 -> 8 | H29: 8 | O29: 8
A30: Pool | B30: 9:00am-5:30pm | C30: Raquel Cardoso | D30: =SUM(E30:K30,L30:R30)/2 -> 16 | H30: 8 | I30: 8 | O30: 8 | P30: 8
A31: Pool | B31: 9:00am-5:30pm | C31: Gilberto Santos | D31: =SUM(E31:K31,L31:R31)/2 -> 16 | E31: 8 | K31: 8 | L31: 8 | R31: 8
C32: Staff by 9am | E32: =COUNT(E7:E15,E17:E24,#REF!,E27:E31) -> 6 | F32: =COUNT(F7:F15,F17:F24,#REF!,F27:F31) -> 9 | G32: =COUNT(G7:G15,G17:G24,#REF!,G27:G31) -> 8 | H32: =COUNT(H7:H15,H17:H24,#REF!,H27:H31) -> 12 | I32: =COUNT(I7:I15,I17:I24,#REF!,I27:I31) -> 11 | J32: =COUNT(J7:J15,J17:J24,#REF!,J27:J31) -> 9 | K32: =COUNT(K7:K15,K17:K24,#REF!,K27:K31) -> 7 | L32: =COUNT(L7:L15,L17:L24,#REF!,L27:L31) -> 6 | ... R32: =COUNT(R7:R15,R17:R24,#REF!,R27:R31) -> 6
A33: Pool | B33: 10:00am-6:30pm | C33: Adhika Tahija | D33: =SUM(E33:K33,L33:R33)/2 -> 16 | G33: 8 | J33: 8 | O33: 8 | Q33: 8
A34: Pool | B34: 10:00am-6:30pm | C34: Maxwell Miller | D34: =SUM(E34:K34,L34:R34)/2 -> 32 | F34: 8 | G34: 8 | H34: 8 | J34: 8 | M34: 8 | N34: 8 | O34: 8 | Q34: 8
A35: Pool | B35: 10:00am-6:30pm | C35: Joshua Thompson | D35: =SUM(E35:K35,L35:R35)/2 -> 8 | K35: 8 | L35: 8
A36: Pool | B36: 10:00am-6:30pm | C36: Blair Alexander | D36: =SUM(E36:K36,L36:R36)/2 -> 40 | E36: 8 | G36: 8 | H36: 8 | I36: 8 | J36: 8 | M36: 8 | N36: 8 | O36: 8 | P36: 8 | R36: 8
A37: Pool | B37: 10:00am-6:30pm | C37: Aaron Hoglund | D37: =SUM(E37:K37,L37:R37)/2 -> 24 | F37: 8 | G37: 8 | J37: 8 | M37: 8 | N37: 8 | Q37: 8
